/local/var/spool/slurmd/job20309464/slurm_script: line 18: cd: /scratch/OParcels_runs/MOAD/analysis-jose/Graham: No such file or directory
Traceback (most recent call last):
  File "/home/jvalenti/miniforge3/envs/Parcels_24/lib/python3.11/site-packages/xarray/backends/file_manager.py", line 211, in _acquire_with_cache_info
    file = self._cache[self._key]
           ~~~~~~~~~~~^^^^^^^^^^^
  File "/home/jvalenti/miniforge3/envs/Parcels_24/lib/python3.11/site-packages/xarray/backends/lru_cache.py", line 56, in __getitem__
    value = self._cache[key]
            ~~~~~~~~~~~^^^^^
KeyError: [<class 'netCDF4._netCDF4.Dataset'>, ('/home/jvalenti/projects/rrg-allen/jvalenti/restartruns/Parcels.nc',), 'a', (('clobber', True), ('diskless', False), ('format', 'NETCDF4'), ('persist', False)), '6fbd4a8b-7faa-4f73-880a-1247b4bda2a1']

During handling of the above exception, another exception occurred:

Traceback (most recent call last):
  File "<frozen runpy>", line 198, in _run_module_as_main
  File "<frozen runpy>", line 88, in _run_code
  File "/home/jvalenti/MOAD/analysis-jose/Graham/Plastics_MCrestart.py", line 158, in <module>
    Restart_OP(config)
  File "/home/jvalenti/MOAD/analysis-jose/Graham/Plastics_MCrestart.py", line 143, in Restart_OP
    ds.to_netcdf('/home/jvalenti/projects/rrg-allen/jvalenti/restart'+names+'.nc')
  File "/home/jvalenti/miniforge3/envs/Parcels_24/lib/python3.11/site-packages/xarray/core/dataset.py", line 2310, in to_netcdf
    return to_netcdf(  # type: ignore  # mypy cannot resolve the overloads:(
           ^^^^^^^^^^^^^^^^^^^^^^^^^^^^^^^^^^^^^^^^^^^^^^^^^^^^^^^^^^^^^^^^^
  File "/home/jvalenti/miniforge3/envs/Parcels_24/lib/python3.11/site-packages/xarray/backends/api.py", line 1298, in to_netcdf
    store = store_open(target, mode, format, group, **kwargs)
            ^^^^^^^^^^^^^^^^^^^^^^^^^^^^^^^^^^^^^^^^^^^^^^^^^
  File "/home/jvalenti/miniforge3/envs/Parcels_24/lib/python3.11/site-packages/xarray/backends/netCDF4_.py", line 400, in open
    return cls(manager, group=group, mode=mode, lock=lock, autoclose=autoclose)
           ^^^^^^^^^^^^^^^^^^^^^^^^^^^^^^^^^^^^^^^^^^^^^^^^^^^^^^^^^^^^^^^^^^^^
  File "/home/jvalenti/miniforge3/envs/Parcels_24/lib/python3.11/site-packages/xarray/backends/netCDF4_.py", line 347, in __init__
    self.format = self.ds.data_model
                  ^^^^^^^
  File "/home/jvalenti/miniforge3/envs/Parcels_24/lib/python3.11/site-packages/xarray/backends/netCDF4_.py", line 409, in ds
    return self._acquire()
           ^^^^^^^^^^^^^^^
  File "/home/jvalenti/miniforge3/envs/Parcels_24/lib/python3.11/site-packages/xarray/backends/netCDF4_.py", line 403, in _acquire
    with self._manager.acquire_context(needs_lock) as root:
  File "/home/jvalenti/miniforge3/envs/Parcels_24/lib/python3.11/contextlib.py", line 137, in __enter__
    return next(self.gen)
           ^^^^^^^^^^^^^^
  File "/home/jvalenti/miniforge3/envs/Parcels_24/lib/python3.11/site-packages/xarray/backends/file_manager.py", line 199, in acquire_context
    file, cached = self._acquire_with_cache_info(needs_lock)
                   ^^^^^^^^^^^^^^^^^^^^^^^^^^^^^^^^^^^^^^^^^
  File "/home/jvalenti/miniforge3/envs/Parcels_24/lib/python3.11/site-packages/xarray/backends/file_manager.py", line 217, in _acquire_with_cache_info
    file = self._opener(*self._args, **kwargs)
           ^^^^^^^^^^^^^^^^^^^^^^^^^^^^^^^^^^^
  File "src/netCDF4/_netCDF4.pyx", line 2469, in netCDF4._netCDF4.Dataset.__init__
  File "src/netCDF4/_netCDF4.pyx", line 2028, in netCDF4._netCDF4._ensure_nc_success
PermissionError: [Errno 13] Permission denied: '/home/jvalenti/projects/rrg-allen/jvalenti/restartruns/Parcels.nc'
Traceback (most recent call last):
  File "/home/jvalenti/miniforge3/envs/Parcels_24/lib/python3.11/site-packages/xarray/backends/file_manager.py", line 211, in _acquire_with_cache_info
    file = self._cache[self._key]
           ~~~~~~~~~~~^^^^^^^^^^^
  File "/home/jvalenti/miniforge3/envs/Parcels_24/lib/python3.11/site-packages/xarray/backends/lru_cache.py", line 56, in __getitem__
    value = self._cache[key]
            ~~~~~~~~~~~^^^^^
KeyError: [<class 'netCDF4._netCDF4.Dataset'>, ('/home/jvalenti/projects/rrg-allen/jvalenti/restartruns/Parcels.nc',), 'a', (('clobber', True), ('diskless', False), ('format', 'NETCDF4'), ('persist', False)), '6bf21170-ac04-4c6c-af99-3cbacd7ba05b']

During handling of the above exception, another exception occurred:

Traceback (most recent call last):
  File "<frozen runpy>", line 198, in _run_module_as_main
  File "<frozen runpy>", line 88, in _run_code
  File "/home/jvalenti/MOAD/analysis-jose/Graham/Plastics_MCrestart.py", line 158, in <module>
    Restart_OP(config)
  File "/home/jvalenti/MOAD/analysis-jose/Graham/Plastics_MCrestart.py", line 143, in Restart_OP
    ds.to_netcdf('/home/jvalenti/projects/rrg-allen/jvalenti/restart'+names+'.nc')
  File "/home/jvalenti/miniforge3/envs/Parcels_24/lib/python3.11/site-packages/xarray/core/dataset.py", line 2310, in to_netcdf
    return to_netcdf(  # type: ignore  # mypy cannot resolve the overloads:(
           ^^^^^^^^^^^^^^^^^^^^^^^^^^^^^^^^^^^^^^^^^^^^^^^^^^^^^^^^^^^^^^^^^
  File "/home/jvalenti/miniforge3/envs/Parcels_24/lib/python3.11/site-packages/xarray/backends/api.py", line 1298, in to_netcdf
    store = store_open(target, mode, format, group, **kwargs)
            ^^^^^^^^^^^^^^^^^^^^^^^^^^^^^^^^^^^^^^^^^^^^^^^^^
  File "/home/jvalenti/miniforge3/envs/Parcels_24/lib/python3.11/site-packages/xarray/backends/netCDF4_.py", line 400, in open
    return cls(manager, group=group, mode=mode, lock=lock, autoclose=autoclose)
           ^^^^^^^^^^^^^^^^^^^^^^^^^^^^^^^^^^^^^^^^^^^^^^^^^^^^^^^^^^^^^^^^^^^^
  File "/home/jvalenti/miniforge3/envs/Parcels_24/lib/python3.11/site-packages/xarray/backends/netCDF4_.py", line 347, in __init__
    self.format = self.ds.data_model
                  ^^^^^^^
  File "/home/jvalenti/miniforge3/envs/Parcels_24/lib/python3.11/site-packages/xarray/backends/netCDF4_.py", line 409, in ds
    return self._acquire()
           ^^^^^^^^^^^^^^^
  File "/home/jvalenti/miniforge3/envs/Parcels_24/lib/python3.11/site-packages/xarray/backends/netCDF4_.py", line 403, in _acquire
    with self._manager.acquire_context(needs_lock) as root:
  File "/home/jvalenti/miniforge3/envs/Parcels_24/lib/python3.11/contextlib.py", line 137, in __enter__
    return next(self.gen)
           ^^^^^^^^^^^^^^
  File "/home/jvalenti/miniforge3/envs/Parcels_24/lib/python3.11/site-packages/xarray/backends/file_manager.py", line 199, in acquire_context
    file, cached = self._acquire_with_cache_info(needs_lock)
                   ^^^^^^^^^^^^^^^^^^^^^^^^^^^^^^^^^^^^^^^^^
  File "/home/jvalenti/miniforge3/envs/Parcels_24/lib/python3.11/site-packages/xarray/backends/file_manager.py", line 217, in _acquire_with_cache_info
    file = self._opener(*self._args, **kwargs)
           ^^^^^^^^^^^^^^^^^^^^^^^^^^^^^^^^^^^
  File "src/netCDF4/_netCDF4.pyx", line 2469, in netCDF4._netCDF4.Dataset.__init__
  File "src/netCDF4/_netCDF4.pyx", line 2028, in netCDF4._netCDF4._ensure_nc_success
PermissionError: [Errno 13] Permission denied: '/home/jvalenti/projects/rrg-allen/jvalenti/restartruns/Parcels.nc'
Traceback (most recent call last):
  File "/home/jvalenti/miniforge3/envs/Parcels_24/lib/python3.11/site-packages/xarray/backends/file_manager.py", line 211, in _acquire_with_cache_info
    file = self._cache[self._key]
           ~~~~~~~~~~~^^^^^^^^^^^
  File "/home/jvalenti/miniforge3/envs/Parcels_24/lib/python3.11/site-packages/xarray/backends/lru_cache.py", line 56, in __getitem__
    value = self._cache[key]
            ~~~~~~~~~~~^^^^^
KeyError: [<class 'netCDF4._netCDF4.Dataset'>, ('/home/jvalenti/projects/rrg-allen/jvalenti/restartruns/Parcels.nc',), 'a', (('clobber', True), ('diskless', False), ('format', 'NETCDF4'), ('persist', False)), '7676a7a8-e773-4581-92bf-96f0ca65c522']

During handling of the above exception, another exception occurred:

Traceback (most recent call last):
  File "<frozen runpy>", line 198, in _run_module_as_main
  File "<frozen runpy>", line 88, in _run_code
  File "/home/jvalenti/MOAD/analysis-jose/Graham/Plastics_MCrestart.py", line 158, in <module>
    Restart_OP(config)
  File "/home/jvalenti/MOAD/analysis-jose/Graham/Plastics_MCrestart.py", line 143, in Restart_OP
    ds.to_netcdf('/home/jvalenti/projects/rrg-allen/jvalenti/restart'+names+'.nc')
  File "/home/jvalenti/miniforge3/envs/Parcels_24/lib/python3.11/site-packages/xarray/core/dataset.py", line 2310, in to_netcdf
    return to_netcdf(  # type: ignore  # mypy cannot resolve the overloads:(
           ^^^^^^^^^^^^^^^^^^^^^^^^^^^^^^^^^^^^^^^^^^^^^^^^^^^^^^^^^^^^^^^^^
  File "/home/jvalenti/miniforge3/envs/Parcels_24/lib/python3.11/site-packages/xarray/backends/api.py", line 1298, in to_netcdf
    store = store_open(target, mode, format, group, **kwargs)
            ^^^^^^^^^^^^^^^^^^^^^^^^^^^^^^^^^^^^^^^^^^^^^^^^^
  File "/home/jvalenti/miniforge3/envs/Parcels_24/lib/python3.11/site-packages/xarray/backends/netCDF4_.py", line 400, in open
    return cls(manager, group=group, mode=mode, lock=lock, autoclose=autoclose)
           ^^^^^^^^^^^^^^^^^^^^^^^^^^^^^^^^^^^^^^^^^^^^^^^^^^^^^^^^^^^^^^^^^^^^
  File "/home/jvalenti/miniforge3/envs/Parcels_24/lib/python3.11/site-packages/xarray/backends/netCDF4_.py", line 347, in __init__
    self.format = self.ds.data_model
                  ^^^^^^^
  File "/home/jvalenti/miniforge3/envs/Parcels_24/lib/python3.11/site-packages/xarray/backends/netCDF4_.py", line 409, in ds
    return self._acquire()
           ^^^^^^^^^^^^^^^
  File "/home/jvalenti/miniforge3/envs/Parcels_24/lib/python3.11/site-packages/xarray/backends/netCDF4_.py", line 403, in _acquire
    with self._manager.acquire_context(needs_lock) as root:
  File "/home/jvalenti/miniforge3/envs/Parcels_24/lib/python3.11/contextlib.py", line 137, in __enter__
    return next(self.gen)
           ^^^^^^^^^^^^^^
  File "/home/jvalenti/miniforge3/envs/Parcels_24/lib/python3.11/site-packages/xarray/backends/file_manager.py", line 199, in acquire_context
    file, cached = self._acquire_with_cache_info(needs_lock)
                   ^^^^^^^^^^^^^^^^^^^^^^^^^^^^^^^^^^^^^^^^^
  File "/home/jvalenti/miniforge3/envs/Parcels_24/lib/python3.11/site-packages/xarray/backends/file_manager.py", line 217, in _acquire_with_cache_info
    file = self._opener(*self._args, **kwargs)
           ^^^^^^^^^^^^^^^^^^^^^^^^^^^^^^^^^^^
  File "src/netCDF4/_netCDF4.pyx", line 2469, in netCDF4._netCDF4.Dataset.__init__
  File "src/netCDF4/_netCDF4.pyx", line 2028, in netCDF4._netCDF4._ensure_nc_success
PermissionError: [Errno 13] Permission denied: '/home/jvalenti/projects/rrg-allen/jvalenti/restartruns/Parcels.nc'
Traceback (most recent call last):
  File "/home/jvalenti/miniforge3/envs/Parcels_24/lib/python3.11/site-packages/xarray/backends/file_manager.py", line 211, in _acquire_with_cache_info
    file = self._cache[self._key]
           ~~~~~~~~~~~^^^^^^^^^^^
  File "/home/jvalenti/miniforge3/envs/Parcels_24/lib/python3.11/site-packages/xarray/backends/lru_cache.py", line 56, in __getitem__
    value = self._cache[key]
            ~~~~~~~~~~~^^^^^
KeyError: [<class 'netCDF4._netCDF4.Dataset'>, ('/home/jvalenti/projects/rrg-allen/jvalenti/restartruns/Parcels.nc',), 'a', (('clobber', True), ('diskless', False), ('format', 'NETCDF4'), ('persist', False)), '7847ccf9-e7f9-4e28-af1e-c2c146c5491f']

During handling of the above exception, another exception occurred:

Traceback (most recent call last):
  File "<frozen runpy>", line 198, in _run_module_as_main
  File "<frozen runpy>", line 88, in _run_code
  File "/home/jvalenti/MOAD/analysis-jose/Graham/Plastics_MCrestart.py", line 158, in <module>
    Restart_OP(config)
  File "/home/jvalenti/MOAD/analysis-jose/Graham/Plastics_MCrestart.py", line 143, in Restart_OP
    ds.to_netcdf('/home/jvalenti/projects/rrg-allen/jvalenti/restart'+names+'.nc')
  File "/home/jvalenti/miniforge3/envs/Parcels_24/lib/python3.11/site-packages/xarray/core/dataset.py", line 2310, in to_netcdf
    return to_netcdf(  # type: ignore  # mypy cannot resolve the overloads:(
           ^^^^^^^^^^^^^^^^^^^^^^^^^^^^^^^^^^^^^^^^^^^^^^^^^^^^^^^^^^^^^^^^^
  File "/home/jvalenti/miniforge3/envs/Parcels_24/lib/python3.11/site-packages/xarray/backends/api.py", line 1298, in to_netcdf
    store = store_open(target, mode, format, group, **kwargs)
            ^^^^^^^^^^^^^^^^^^^^^^^^^^^^^^^^^^^^^^^^^^^^^^^^^
  File "/home/jvalenti/miniforge3/envs/Parcels_24/lib/python3.11/site-packages/xarray/backends/netCDF4_.py", line 400, in open
    return cls(manager, group=group, mode=mode, lock=lock, autoclose=autoclose)
           ^^^^^^^^^^^^^^^^^^^^^^^^^^^^^^^^^^^^^^^^^^^^^^^^^^^^^^^^^^^^^^^^^^^^
  File "/home/jvalenti/miniforge3/envs/Parcels_24/lib/python3.11/site-packages/xarray/backends/netCDF4_.py", line 347, in __init__
    self.format = self.ds.data_model
                  ^^^^^^^
  File "/home/jvalenti/miniforge3/envs/Parcels_24/lib/python3.11/site-packages/xarray/backends/netCDF4_.py", line 409, in ds
    return self._acquire()
           ^^^^^^^^^^^^^^^
  File "/home/jvalenti/miniforge3/envs/Parcels_24/lib/python3.11/site-packages/xarray/backends/netCDF4_.py", line 403, in _acquire
    with self._manager.acquire_context(needs_lock) as root:
  File "/home/jvalenti/miniforge3/envs/Parcels_24/lib/python3.11/contextlib.py", line 137, in __enter__
    return next(self.gen)
           ^^^^^^^^^^^^^^
  File "/home/jvalenti/miniforge3/envs/Parcels_24/lib/python3.11/site-packages/xarray/backends/file_manager.py", line 199, in acquire_context
    file, cached = self._acquire_with_cache_info(needs_lock)
                   ^^^^^^^^^^^^^^^^^^^^^^^^^^^^^^^^^^^^^^^^^
  File "/home/jvalenti/miniforge3/envs/Parcels_24/lib/python3.11/site-packages/xarray/backends/file_manager.py", line 217, in _acquire_with_cache_info
    file = self._opener(*self._args, **kwargs)
           ^^^^^^^^^^^^^^^^^^^^^^^^^^^^^^^^^^^
  File "src/netCDF4/_netCDF4.pyx", line 2469, in netCDF4._netCDF4.Dataset.__init__
  File "src/netCDF4/_netCDF4.pyx", line 2028, in netCDF4._netCDF4._ensure_nc_success
PermissionError: [Errno 13] Permission denied: '/home/jvalenti/projects/rrg-allen/jvalenti/restartruns/Parcels.nc'
Traceback (most recent call last):
  File "/home/jvalenti/miniforge3/envs/Parcels_24/lib/python3.11/site-packages/xarray/backends/file_manager.py", line 211, in _acquire_with_cache_info
    file = self._cache[self._key]
           ~~~~~~~~~~~^^^^^^^^^^^
  File "/home/jvalenti/miniforge3/envs/Parcels_24/lib/python3.11/site-packages/xarray/backends/lru_cache.py", line 56, in __getitem__
    value = self._cache[key]
            ~~~~~~~~~~~^^^^^
KeyError: [<class 'netCDF4._netCDF4.Dataset'>, ('/home/jvalenti/projects/rrg-allen/jvalenti/restartruns/Parcels.nc',), 'a', (('clobber', True), ('diskless', False), ('format', 'NETCDF4'), ('persist', False)), 'f2632152-e404-4036-9a27-80cec42ab916']

During handling of the above exception, another exception occurred:

Traceback (most recent call last):
  File "<frozen runpy>", line 198, in _run_module_as_main
  File "<frozen runpy>", line 88, in _run_code
  File "/home/jvalenti/MOAD/analysis-jose/Graham/Plastics_MCrestart.py", line 158, in <module>
    Restart_OP(config)
  File "/home/jvalenti/MOAD/analysis-jose/Graham/Plastics_MCrestart.py", line 143, in Restart_OP
    ds.to_netcdf('/home/jvalenti/projects/rrg-allen/jvalenti/restart'+names+'.nc')
  File "/home/jvalenti/miniforge3/envs/Parcels_24/lib/python3.11/site-packages/xarray/core/dataset.py", line 2310, in to_netcdf
    return to_netcdf(  # type: ignore  # mypy cannot resolve the overloads:(
           ^^^^^^^^^^^^^^^^^^^^^^^^^^^^^^^^^^^^^^^^^^^^^^^^^^^^^^^^^^^^^^^^^
  File "/home/jvalenti/miniforge3/envs/Parcels_24/lib/python3.11/site-packages/xarray/backends/api.py", line 1298, in to_netcdf
    store = store_open(target, mode, format, group, **kwargs)
            ^^^^^^^^^^^^^^^^^^^^^^^^^^^^^^^^^^^^^^^^^^^^^^^^^
  File "/home/jvalenti/miniforge3/envs/Parcels_24/lib/python3.11/site-packages/xarray/backends/netCDF4_.py", line 400, in open
    return cls(manager, group=group, mode=mode, lock=lock, autoclose=autoclose)
           ^^^^^^^^^^^^^^^^^^^^^^^^^^^^^^^^^^^^^^^^^^^^^^^^^^^^^^^^^^^^^^^^^^^^
  File "/home/jvalenti/miniforge3/envs/Parcels_24/lib/python3.11/site-packages/xarray/backends/netCDF4_.py", line 347, in __init__
    self.format = self.ds.data_model
                  ^^^^^^^
  File "/home/jvalenti/miniforge3/envs/Parcels_24/lib/python3.11/site-packages/xarray/backends/netCDF4_.py", line 409, in ds
    return self._acquire()
           ^^^^^^^^^^^^^^^
  File "/home/jvalenti/miniforge3/envs/Parcels_24/lib/python3.11/site-packages/xarray/backends/netCDF4_.py", line 403, in _acquire
    with self._manager.acquire_context(needs_lock) as root:
  File "/home/jvalenti/miniforge3/envs/Parcels_24/lib/python3.11/contextlib.py", line 137, in __enter__
    return next(self.gen)
           ^^^^^^^^^^^^^^
  File "/home/jvalenti/miniforge3/envs/Parcels_24/lib/python3.11/site-packages/xarray/backends/file_manager.py", line 199, in acquire_context
    file, cached = self._acquire_with_cache_info(needs_lock)
                   ^^^^^^^^^^^^^^^^^^^^^^^^^^^^^^^^^^^^^^^^^
  File "/home/jvalenti/miniforge3/envs/Parcels_24/lib/python3.11/site-packages/xarray/backends/file_manager.py", line 217, in _acquire_with_cache_info
    file = self._opener(*self._args, **kwargs)
           ^^^^^^^^^^^^^^^^^^^^^^^^^^^^^^^^^^^
  File "src/netCDF4/_netCDF4.pyx", line 2469, in netCDF4._netCDF4.Dataset.__init__
  File "src/netCDF4/_netCDF4.pyx", line 2028, in netCDF4._netCDF4._ensure_nc_success
PermissionError: [Errno 13] Permission denied: '/home/jvalenti/projects/rrg-allen/jvalenti/restartruns/Parcels.nc'
Traceback (most recent call last):
  File "/home/jvalenti/miniforge3/envs/Parcels_24/lib/python3.11/site-packages/xarray/backends/file_manager.py", line 211, in _acquire_with_cache_info
    file = self._cache[self._key]
           ~~~~~~~~~~~^^^^^^^^^^^
  File "/home/jvalenti/miniforge3/envs/Parcels_24/lib/python3.11/site-packages/xarray/backends/lru_cache.py", line 56, in __getitem__
    value = self._cache[key]
            ~~~~~~~~~~~^^^^^
KeyError: [<class 'netCDF4._netCDF4.Dataset'>, ('/home/jvalenti/projects/rrg-allen/jvalenti/restartruns/Parcels.nc',), 'a', (('clobber', True), ('diskless', False), ('format', 'NETCDF4'), ('persist', False)), '08cb958f-c6ba-4ba0-af10-41f69861be0e']

During handling of the above exception, another exception occurred:

Traceback (most recent call last):
  File "<frozen runpy>", line 198, in _run_module_as_main
  File "<frozen runpy>", line 88, in _run_code
  File "/home/jvalenti/MOAD/analysis-jose/Graham/Plastics_MCrestart.py", line 158, in <module>
    Restart_OP(config)
  File "/home/jvalenti/MOAD/analysis-jose/Graham/Plastics_MCrestart.py", line 143, in Restart_OP
    ds.to_netcdf('/home/jvalenti/projects/rrg-allen/jvalenti/restart'+names+'.nc')
  File "/home/jvalenti/miniforge3/envs/Parcels_24/lib/python3.11/site-packages/xarray/core/dataset.py", line 2310, in to_netcdf
    return to_netcdf(  # type: ignore  # mypy cannot resolve the overloads:(
           ^^^^^^^^^^^^^^^^^^^^^^^^^^^^^^^^^^^^^^^^^^^^^^^^^^^^^^^^^^^^^^^^^
  File "/home/jvalenti/miniforge3/envs/Parcels_24/lib/python3.11/site-packages/xarray/backends/api.py", line 1298, in to_netcdf
    store = store_open(target, mode, format, group, **kwargs)
            ^^^^^^^^^^^^^^^^^^^^^^^^^^^^^^^^^^^^^^^^^^^^^^^^^
  File "/home/jvalenti/miniforge3/envs/Parcels_24/lib/python3.11/site-packages/xarray/backends/netCDF4_.py", line 400, in open
    return cls(manager, group=group, mode=mode, lock=lock, autoclose=autoclose)
           ^^^^^^^^^^^^^^^^^^^^^^^^^^^^^^^^^^^^^^^^^^^^^^^^^^^^^^^^^^^^^^^^^^^^
  File "/home/jvalenti/miniforge3/envs/Parcels_24/lib/python3.11/site-packages/xarray/backends/netCDF4_.py", line 347, in __init__
    self.format = self.ds.data_model
                  ^^^^^^^
  File "/home/jvalenti/miniforge3/envs/Parcels_24/lib/python3.11/site-packages/xarray/backends/netCDF4_.py", line 409, in ds
    return self._acquire()
           ^^^^^^^^^^^^^^^
  File "/home/jvalenti/miniforge3/envs/Parcels_24/lib/python3.11/site-packages/xarray/backends/netCDF4_.py", line 403, in _acquire
    with self._manager.acquire_context(needs_lock) as root:
  File "/home/jvalenti/miniforge3/envs/Parcels_24/lib/python3.11/contextlib.py", line 137, in __enter__
    return next(self.gen)
           ^^^^^^^^^^^^^^
  File "/home/jvalenti/miniforge3/envs/Parcels_24/lib/python3.11/site-packages/xarray/backends/file_manager.py", line 199, in acquire_context
    file, cached = self._acquire_with_cache_info(needs_lock)
                   ^^^^^^^^^^^^^^^^^^^^^^^^^^^^^^^^^^^^^^^^^
  File "/home/jvalenti/miniforge3/envs/Parcels_24/lib/python3.11/site-packages/xarray/backends/file_manager.py", line 217, in _acquire_with_cache_info
    file = self._opener(*self._args, **kwargs)
           ^^^^^^^^^^^^^^^^^^^^^^^^^^^^^^^^^^^
  File "src/netCDF4/_netCDF4.pyx", line 2469, in netCDF4._netCDF4.Dataset.__init__
  File "src/netCDF4/_netCDF4.pyx", line 2028, in netCDF4._netCDF4._ensure_nc_success
PermissionError: [Errno 13] Permission denied: '/home/jvalenti/projects/rrg-allen/jvalenti/restartruns/Parcels.nc'
Traceback (most recent call last):
  File "/home/jvalenti/miniforge3/envs/Parcels_24/lib/python3.11/site-packages/xarray/backends/file_manager.py", line 211, in _acquire_with_cache_info
    file = self._cache[self._key]
           ~~~~~~~~~~~^^^^^^^^^^^
  File "/home/jvalenti/miniforge3/envs/Parcels_24/lib/python3.11/site-packages/xarray/backends/lru_cache.py", line 56, in __getitem__
    value = self._cache[key]
            ~~~~~~~~~~~^^^^^
KeyError: [<class 'netCDF4._netCDF4.Dataset'>, ('/home/jvalenti/projects/rrg-allen/jvalenti/restartruns/Parcels.nc',), 'a', (('clobber', True), ('diskless', False), ('format', 'NETCDF4'), ('persist', False)), '13b882e7-247d-4337-b30d-d12729b91e56']

During handling of the above exception, another exception occurred:

Traceback (most recent call last):
  File "<frozen runpy>", line 198, in _run_module_as_main
  File "<frozen runpy>", line 88, in _run_code
  File "/home/jvalenti/MOAD/analysis-jose/Graham/Plastics_MCrestart.py", line 158, in <module>
    Restart_OP(config)
  File "/home/jvalenti/MOAD/analysis-jose/Graham/Plastics_MCrestart.py", line 143, in Restart_OP
    ds.to_netcdf('/home/jvalenti/projects/rrg-allen/jvalenti/restart'+names+'.nc')
  File "/home/jvalenti/miniforge3/envs/Parcels_24/lib/python3.11/site-packages/xarray/core/dataset.py", line 2310, in to_netcdf
    return to_netcdf(  # type: ignore  # mypy cannot resolve the overloads:(
           ^^^^^^^^^^^^^^^^^^^^^^^^^^^^^^^^^^^^^^^^^^^^^^^^^^^^^^^^^^^^^^^^^
  File "/home/jvalenti/miniforge3/envs/Parcels_24/lib/python3.11/site-packages/xarray/backends/api.py", line 1298, in to_netcdf
    store = store_open(target, mode, format, group, **kwargs)
            ^^^^^^^^^^^^^^^^^^^^^^^^^^^^^^^^^^^^^^^^^^^^^^^^^
  File "/home/jvalenti/miniforge3/envs/Parcels_24/lib/python3.11/site-packages/xarray/backends/netCDF4_.py", line 400, in open
    return cls(manager, group=group, mode=mode, lock=lock, autoclose=autoclose)
           ^^^^^^^^^^^^^^^^^^^^^^^^^^^^^^^^^^^^^^^^^^^^^^^^^^^^^^^^^^^^^^^^^^^^
  File "/home/jvalenti/miniforge3/envs/Parcels_24/lib/python3.11/site-packages/xarray/backends/netCDF4_.py", line 347, in __init__
    self.format = self.ds.data_model
                  ^^^^^^^
  File "/home/jvalenti/miniforge3/envs/Parcels_24/lib/python3.11/site-packages/xarray/backends/netCDF4_.py", line 409, in ds
    return self._acquire()
           ^^^^^^^^^^^^^^^
  File "/home/jvalenti/miniforge3/envs/Parcels_24/lib/python3.11/site-packages/xarray/backends/netCDF4_.py", line 403, in _acquire
    with self._manager.acquire_context(needs_lock) as root:
  File "/home/jvalenti/miniforge3/envs/Parcels_24/lib/python3.11/contextlib.py", line 137, in __enter__
    return next(self.gen)
           ^^^^^^^^^^^^^^
  File "/home/jvalenti/miniforge3/envs/Parcels_24/lib/python3.11/site-packages/xarray/backends/file_manager.py", line 199, in acquire_context
    file, cached = self._acquire_with_cache_info(needs_lock)
                   ^^^^^^^^^^^^^^^^^^^^^^^^^^^^^^^^^^^^^^^^^
  File "/home/jvalenti/miniforge3/envs/Parcels_24/lib/python3.11/site-packages/xarray/backends/file_manager.py", line 217, in _acquire_with_cache_info
    file = self._opener(*self._args, **kwargs)
           ^^^^^^^^^^^^^^^^^^^^^^^^^^^^^^^^^^^
  File "src/netCDF4/_netCDF4.pyx", line 2469, in netCDF4._netCDF4.Dataset.__init__
  File "src/netCDF4/_netCDF4.pyx", line 2028, in netCDF4._netCDF4._ensure_nc_success
PermissionError: [Errno 13] Permission denied: '/home/jvalenti/projects/rrg-allen/jvalenti/restartruns/Parcels.nc'
Traceback (most recent call last):
  File "<frozen runpy>", line 198, in _run_module_as_main
  File "<frozen runpy>", line 88, in _run_code
  File "/home/jvalenti/MOAD/analysis-jose/Graham/Plastics_MCrestart.py", line 158, in <module>
    Restart_OP(config)
  File "/home/jvalenti/MOAD/analysis-jose/Graham/Plastics_MCrestart.py", line 138, in Restart_OP
    [xr.open_zarr(f) for f in files],
    ^^^^^^^^^^^^^^^^^^^^^^^^^^^^^^^^
  File "/home/jvalenti/MOAD/analysis-jose/Graham/Plastics_MCrestart.py", line 138, in <listcomp>
    [xr.open_zarr(f) for f in files],
     ^^^^^^^^^^^^^^^
  File "/home/jvalenti/miniforge3/envs/Parcels_24/lib/python3.11/site-packages/xarray/backends/zarr.py", line 944, in open_zarr
    ds = open_dataset(
         ^^^^^^^^^^^^^
  File "/home/jvalenti/miniforge3/envs/Parcels_24/lib/python3.11/site-packages/xarray/backends/api.py", line 572, in open_dataset
    backend_ds = backend.open_dataset(
                 ^^^^^^^^^^^^^^^^^^^^^
  File "/home/jvalenti/miniforge3/envs/Parcels_24/lib/python3.11/site-packages/xarray/backends/zarr.py", line 1026, in open_dataset
    ds = store_entrypoint.open_dataset(
         ^^^^^^^^^^^^^^^^^^^^^^^^^^^^^^
  File "/home/jvalenti/miniforge3/envs/Parcels_24/lib/python3.11/site-packages/xarray/backends/store.py", line 58, in open_dataset
    ds = Dataset(vars, attrs=attrs)
         ^^^^^^^^^^^^^^^^^^^^^^^^^^
  File "/home/jvalenti/miniforge3/envs/Parcels_24/lib/python3.11/site-packages/xarray/core/dataset.py", line 701, in __init__
    variables, coord_names, dims, indexes, _ = merge_data_and_coords(
                                               ^^^^^^^^^^^^^^^^^^^^^^
  File "/home/jvalenti/miniforge3/envs/Parcels_24/lib/python3.11/site-packages/xarray/core/dataset.py", line 430, in merge_data_and_coords
    return merge_core(
           ^^^^^^^^^^^
  File "/home/jvalenti/miniforge3/envs/Parcels_24/lib/python3.11/site-packages/xarray/core/merge.py", line 724, in merge_core
    dims = calculate_dimensions(variables)
           ^^^^^^^^^^^^^^^^^^^^^^^^^^^^^^^
  File "/home/jvalenti/miniforge3/envs/Parcels_24/lib/python3.11/site-packages/xarray/core/variable.py", line 3008, in calculate_dimensions
    raise ValueError(
ValueError: conflicting sizes for dimension 'obs': length 132 on 'alpha' and length 133 on {'trajectory': 'Ub', 'obs': 'Ub'}
Traceback (most recent call last):
  File "<frozen runpy>", line 198, in _run_module_as_main
  File "<frozen runpy>", line 88, in _run_code
  File "/home/jvalenti/MOAD/analysis-jose/Graham/Plastics_MCrestart.py", line 158, in <module>
    Restart_OP(config)
  File "/home/jvalenti/MOAD/analysis-jose/Graham/Plastics_MCrestart.py", line 138, in Restart_OP
    [xr.open_zarr(f) for f in files],
    ^^^^^^^^^^^^^^^^^^^^^^^^^^^^^^^^
  File "/home/jvalenti/MOAD/analysis-jose/Graham/Plastics_MCrestart.py", line 138, in <listcomp>
    [xr.open_zarr(f) for f in files],
     ^^^^^^^^^^^^^^^
  File "/home/jvalenti/miniforge3/envs/Parcels_24/lib/python3.11/site-packages/xarray/backends/zarr.py", line 944, in open_zarr
    ds = open_dataset(
         ^^^^^^^^^^^^^
  File "/home/jvalenti/miniforge3/envs/Parcels_24/lib/python3.11/site-packages/xarray/backends/api.py", line 572, in open_dataset
    backend_ds = backend.open_dataset(
                 ^^^^^^^^^^^^^^^^^^^^^
  File "/home/jvalenti/miniforge3/envs/Parcels_24/lib/python3.11/site-packages/xarray/backends/zarr.py", line 1026, in open_dataset
    ds = store_entrypoint.open_dataset(
         ^^^^^^^^^^^^^^^^^^^^^^^^^^^^^^
  File "/home/jvalenti/miniforge3/envs/Parcels_24/lib/python3.11/site-packages/xarray/backends/store.py", line 58, in open_dataset
    ds = Dataset(vars, attrs=attrs)
         ^^^^^^^^^^^^^^^^^^^^^^^^^^
  File "/home/jvalenti/miniforge3/envs/Parcels_24/lib/python3.11/site-packages/xarray/core/dataset.py", line 701, in __init__
    variables, coord_names, dims, indexes, _ = merge_data_and_coords(
                                               ^^^^^^^^^^^^^^^^^^^^^^
  File "/home/jvalenti/miniforge3/envs/Parcels_24/lib/python3.11/site-packages/xarray/core/dataset.py", line 430, in merge_data_and_coords
    return merge_core(
           ^^^^^^^^^^^
  File "/home/jvalenti/miniforge3/envs/Parcels_24/lib/python3.11/site-packages/xarray/core/merge.py", line 724, in merge_core
    dims = calculate_dimensions(variables)
           ^^^^^^^^^^^^^^^^^^^^^^^^^^^^^^^
  File "/home/jvalenti/miniforge3/envs/Parcels_24/lib/python3.11/site-packages/xarray/core/variable.py", line 3008, in calculate_dimensions
    raise ValueError(
ValueError: conflicting sizes for dimension 'obs': length 144 on 'alpha' and length 145 on {'trajectory': 'Ub', 'obs': 'Ub'}
Traceback (most recent call last):
  File "/home/jvalenti/miniforge3/envs/Parcels_24/lib/python3.11/site-packages/xarray/backends/file_manager.py", line 211, in _acquire_with_cache_info
    file = self._cache[self._key]
           ~~~~~~~~~~~^^^^^^^^^^^
  File "/home/jvalenti/miniforge3/envs/Parcels_24/lib/python3.11/site-packages/xarray/backends/lru_cache.py", line 56, in __getitem__
    value = self._cache[key]
            ~~~~~~~~~~~^^^^^
KeyError: [<class 'netCDF4._netCDF4.Dataset'>, ('/home/jvalenti/projects/rrg-allen/jvalenti/restartruns/Parcels.nc',), 'a', (('clobber', True), ('diskless', False), ('format', 'NETCDF4'), ('persist', False)), '2bdaa22f-be01-400e-8c57-9705813aab2e']

During handling of the above exception, another exception occurred:

Traceback (most recent call last):
  File "<frozen runpy>", line 198, in _run_module_as_main
  File "<frozen runpy>", line 88, in _run_code
  File "/home/jvalenti/MOAD/analysis-jose/Graham/Plastics_MCrestart.py", line 158, in <module>
    Restart_OP(config)
  File "/home/jvalenti/MOAD/analysis-jose/Graham/Plastics_MCrestart.py", line 143, in Restart_OP
    ds.to_netcdf('/home/jvalenti/projects/rrg-allen/jvalenti/restart'+names+'.nc')
  File "/home/jvalenti/miniforge3/envs/Parcels_24/lib/python3.11/site-packages/xarray/core/dataset.py", line 2310, in to_netcdf
    return to_netcdf(  # type: ignore  # mypy cannot resolve the overloads:(
           ^^^^^^^^^^^^^^^^^^^^^^^^^^^^^^^^^^^^^^^^^^^^^^^^^^^^^^^^^^^^^^^^^
  File "/home/jvalenti/miniforge3/envs/Parcels_24/lib/python3.11/site-packages/xarray/backends/api.py", line 1298, in to_netcdf
    store = store_open(target, mode, format, group, **kwargs)
            ^^^^^^^^^^^^^^^^^^^^^^^^^^^^^^^^^^^^^^^^^^^^^^^^^
  File "/home/jvalenti/miniforge3/envs/Parcels_24/lib/python3.11/site-packages/xarray/backends/netCDF4_.py", line 400, in open
    return cls(manager, group=group, mode=mode, lock=lock, autoclose=autoclose)
           ^^^^^^^^^^^^^^^^^^^^^^^^^^^^^^^^^^^^^^^^^^^^^^^^^^^^^^^^^^^^^^^^^^^^
  File "/home/jvalenti/miniforge3/envs/Parcels_24/lib/python3.11/site-packages/xarray/backends/netCDF4_.py", line 347, in __init__
    self.format = self.ds.data_model
                  ^^^^^^^
  File "/home/jvalenti/miniforge3/envs/Parcels_24/lib/python3.11/site-packages/xarray/backends/netCDF4_.py", line 409, in ds
    return self._acquire()
           ^^^^^^^^^^^^^^^
  File "/home/jvalenti/miniforge3/envs/Parcels_24/lib/python3.11/site-packages/xarray/backends/netCDF4_.py", line 403, in _acquire
    with self._manager.acquire_context(needs_lock) as root:
  File "/home/jvalenti/miniforge3/envs/Parcels_24/lib/python3.11/contextlib.py", line 137, in __enter__
    return next(self.gen)
           ^^^^^^^^^^^^^^
  File "/home/jvalenti/miniforge3/envs/Parcels_24/lib/python3.11/site-packages/xarray/backends/file_manager.py", line 199, in acquire_context
    file, cached = self._acquire_with_cache_info(needs_lock)
                   ^^^^^^^^^^^^^^^^^^^^^^^^^^^^^^^^^^^^^^^^^
  File "/home/jvalenti/miniforge3/envs/Parcels_24/lib/python3.11/site-packages/xarray/backends/file_manager.py", line 217, in _acquire_with_cache_info
    file = self._opener(*self._args, **kwargs)
           ^^^^^^^^^^^^^^^^^^^^^^^^^^^^^^^^^^^
  File "src/netCDF4/_netCDF4.pyx", line 2469, in netCDF4._netCDF4.Dataset.__init__
  File "src/netCDF4/_netCDF4.pyx", line 2028, in netCDF4._netCDF4._ensure_nc_success
PermissionError: [Errno 13] Permission denied: '/home/jvalenti/projects/rrg-allen/jvalenti/restartruns/Parcels.nc'
Traceback (most recent call last):
  File "/home/jvalenti/miniforge3/envs/Parcels_24/lib/python3.11/site-packages/xarray/backends/file_manager.py", line 211, in _acquire_with_cache_info
    file = self._cache[self._key]
           ~~~~~~~~~~~^^^^^^^^^^^
  File "/home/jvalenti/miniforge3/envs/Parcels_24/lib/python3.11/site-packages/xarray/backends/lru_cache.py", line 56, in __getitem__
    value = self._cache[key]
            ~~~~~~~~~~~^^^^^
KeyError: [<class 'netCDF4._netCDF4.Dataset'>, ('/home/jvalenti/projects/rrg-allen/jvalenti/restartruns/Parcels.nc',), 'a', (('clobber', True), ('diskless', False), ('format', 'NETCDF4'), ('persist', False)), '464ffe02-9442-4a70-ad35-e09f1ff4e4ee']

During handling of the above exception, another exception occurred:

Traceback (most recent call last):
  File "<frozen runpy>", line 198, in _run_module_as_main
  File "<frozen runpy>", line 88, in _run_code
  File "/home/jvalenti/MOAD/analysis-jose/Graham/Plastics_MCrestart.py", line 158, in <module>
    Restart_OP(config)
  File "/home/jvalenti/MOAD/analysis-jose/Graham/Plastics_MCrestart.py", line 143, in Restart_OP
    ds.to_netcdf('/home/jvalenti/projects/rrg-allen/jvalenti/restart'+names+'.nc')
  File "/home/jvalenti/miniforge3/envs/Parcels_24/lib/python3.11/site-packages/xarray/core/dataset.py", line 2310, in to_netcdf
    return to_netcdf(  # type: ignore  # mypy cannot resolve the overloads:(
           ^^^^^^^^^^^^^^^^^^^^^^^^^^^^^^^^^^^^^^^^^^^^^^^^^^^^^^^^^^^^^^^^^
  File "/home/jvalenti/miniforge3/envs/Parcels_24/lib/python3.11/site-packages/xarray/backends/api.py", line 1298, in to_netcdf
    store = store_open(target, mode, format, group, **kwargs)
            ^^^^^^^^^^^^^^^^^^^^^^^^^^^^^^^^^^^^^^^^^^^^^^^^^
  File "/home/jvalenti/miniforge3/envs/Parcels_24/lib/python3.11/site-packages/xarray/backends/netCDF4_.py", line 400, in open
    return cls(manager, group=group, mode=mode, lock=lock, autoclose=autoclose)
           ^^^^^^^^^^^^^^^^^^^^^^^^^^^^^^^^^^^^^^^^^^^^^^^^^^^^^^^^^^^^^^^^^^^^
  File "/home/jvalenti/miniforge3/envs/Parcels_24/lib/python3.11/site-packages/xarray/backends/netCDF4_.py", line 347, in __init__
    self.format = self.ds.data_model
                  ^^^^^^^
  File "/home/jvalenti/miniforge3/envs/Parcels_24/lib/python3.11/site-packages/xarray/backends/netCDF4_.py", line 409, in ds
    return self._acquire()
           ^^^^^^^^^^^^^^^
  File "/home/jvalenti/miniforge3/envs/Parcels_24/lib/python3.11/site-packages/xarray/backends/netCDF4_.py", line 403, in _acquire
    with self._manager.acquire_context(needs_lock) as root:
  File "/home/jvalenti/miniforge3/envs/Parcels_24/lib/python3.11/contextlib.py", line 137, in __enter__
    return next(self.gen)
           ^^^^^^^^^^^^^^
  File "/home/jvalenti/miniforge3/envs/Parcels_24/lib/python3.11/site-packages/xarray/backends/file_manager.py", line 199, in acquire_context
    file, cached = self._acquire_with_cache_info(needs_lock)
                   ^^^^^^^^^^^^^^^^^^^^^^^^^^^^^^^^^^^^^^^^^
  File "/home/jvalenti/miniforge3/envs/Parcels_24/lib/python3.11/site-packages/xarray/backends/file_manager.py", line 217, in _acquire_with_cache_info
    file = self._opener(*self._args, **kwargs)
           ^^^^^^^^^^^^^^^^^^^^^^^^^^^^^^^^^^^
  File "src/netCDF4/_netCDF4.pyx", line 2469, in netCDF4._netCDF4.Dataset.__init__
  File "src/netCDF4/_netCDF4.pyx", line 2028, in netCDF4._netCDF4._ensure_nc_success
PermissionError: [Errno 13] Permission denied: '/home/jvalenti/projects/rrg-allen/jvalenti/restartruns/Parcels.nc'
Traceback (most recent call last):
  File "/home/jvalenti/miniforge3/envs/Parcels_24/lib/python3.11/site-packages/xarray/backends/file_manager.py", line 211, in _acquire_with_cache_info
    file = self._cache[self._key]
           ~~~~~~~~~~~^^^^^^^^^^^
  File "/home/jvalenti/miniforge3/envs/Parcels_24/lib/python3.11/site-packages/xarray/backends/lru_cache.py", line 56, in __getitem__
    value = self._cache[key]
            ~~~~~~~~~~~^^^^^
KeyError: [<class 'netCDF4._netCDF4.Dataset'>, ('/home/jvalenti/projects/rrg-allen/jvalenti/restartruns/Parcels.nc',), 'a', (('clobber', True), ('diskless', False), ('format', 'NETCDF4'), ('persist', False)), '25f97611-1856-45d8-aa2a-e766fa156e7a']

During handling of the above exception, another exception occurred:

Traceback (most recent call last):
  File "<frozen runpy>", line 198, in _run_module_as_main
  File "<frozen runpy>", line 88, in _run_code
  File "/home/jvalenti/MOAD/analysis-jose/Graham/Plastics_MCrestart.py", line 158, in <module>
    Restart_OP(config)
  File "/home/jvalenti/MOAD/analysis-jose/Graham/Plastics_MCrestart.py", line 143, in Restart_OP
    ds.to_netcdf('/home/jvalenti/projects/rrg-allen/jvalenti/restart'+names+'.nc')
  File "/home/jvalenti/miniforge3/envs/Parcels_24/lib/python3.11/site-packages/xarray/core/dataset.py", line 2310, in to_netcdf
    return to_netcdf(  # type: ignore  # mypy cannot resolve the overloads:(
           ^^^^^^^^^^^^^^^^^^^^^^^^^^^^^^^^^^^^^^^^^^^^^^^^^^^^^^^^^^^^^^^^^
  File "/home/jvalenti/miniforge3/envs/Parcels_24/lib/python3.11/site-packages/xarray/backends/api.py", line 1298, in to_netcdf
    store = store_open(target, mode, format, group, **kwargs)
            ^^^^^^^^^^^^^^^^^^^^^^^^^^^^^^^^^^^^^^^^^^^^^^^^^
  File "/home/jvalenti/miniforge3/envs/Parcels_24/lib/python3.11/site-packages/xarray/backends/netCDF4_.py", line 400, in open
    return cls(manager, group=group, mode=mode, lock=lock, autoclose=autoclose)
           ^^^^^^^^^^^^^^^^^^^^^^^^^^^^^^^^^^^^^^^^^^^^^^^^^^^^^^^^^^^^^^^^^^^^
  File "/home/jvalenti/miniforge3/envs/Parcels_24/lib/python3.11/site-packages/xarray/backends/netCDF4_.py", line 347, in __init__
    self.format = self.ds.data_model
                  ^^^^^^^
  File "/home/jvalenti/miniforge3/envs/Parcels_24/lib/python3.11/site-packages/xarray/backends/netCDF4_.py", line 409, in ds
    return self._acquire()
           ^^^^^^^^^^^^^^^
  File "/home/jvalenti/miniforge3/envs/Parcels_24/lib/python3.11/site-packages/xarray/backends/netCDF4_.py", line 403, in _acquire
    with self._manager.acquire_context(needs_lock) as root:
  File "/home/jvalenti/miniforge3/envs/Parcels_24/lib/python3.11/contextlib.py", line 137, in __enter__
    return next(self.gen)
           ^^^^^^^^^^^^^^
  File "/home/jvalenti/miniforge3/envs/Parcels_24/lib/python3.11/site-packages/xarray/backends/file_manager.py", line 199, in acquire_context
    file, cached = self._acquire_with_cache_info(needs_lock)
                   ^^^^^^^^^^^^^^^^^^^^^^^^^^^^^^^^^^^^^^^^^
  File "/home/jvalenti/miniforge3/envs/Parcels_24/lib/python3.11/site-packages/xarray/backends/file_manager.py", line 217, in _acquire_with_cache_info
    file = self._opener(*self._args, **kwargs)
           ^^^^^^^^^^^^^^^^^^^^^^^^^^^^^^^^^^^
  File "src/netCDF4/_netCDF4.pyx", line 2469, in netCDF4._netCDF4.Dataset.__init__
  File "src/netCDF4/_netCDF4.pyx", line 2028, in netCDF4._netCDF4._ensure_nc_success
PermissionError: [Errno 13] Permission denied: '/home/jvalenti/projects/rrg-allen/jvalenti/restartruns/Parcels.nc'
Traceback (most recent call last):
  File "/home/jvalenti/miniforge3/envs/Parcels_24/lib/python3.11/site-packages/xarray/backends/file_manager.py", line 211, in _acquire_with_cache_info
    file = self._cache[self._key]
           ~~~~~~~~~~~^^^^^^^^^^^
  File "/home/jvalenti/miniforge3/envs/Parcels_24/lib/python3.11/site-packages/xarray/backends/lru_cache.py", line 56, in __getitem__
    value = self._cache[key]
            ~~~~~~~~~~~^^^^^
KeyError: [<class 'netCDF4._netCDF4.Dataset'>, ('/home/jvalenti/projects/rrg-allen/jvalenti/restartruns/Parcels.nc',), 'a', (('clobber', True), ('diskless', False), ('format', 'NETCDF4'), ('persist', False)), '46a71efe-7465-42d2-b60e-80cdf8e18c02']

During handling of the above exception, another exception occurred:

Traceback (most recent call last):
  File "<frozen runpy>", line 198, in _run_module_as_main
  File "<frozen runpy>", line 88, in _run_code
  File "/home/jvalenti/MOAD/analysis-jose/Graham/Plastics_MCrestart.py", line 158, in <module>
    Restart_OP(config)
  File "/home/jvalenti/MOAD/analysis-jose/Graham/Plastics_MCrestart.py", line 143, in Restart_OP
    ds.to_netcdf('/home/jvalenti/projects/rrg-allen/jvalenti/restart'+names+'.nc')
  File "/home/jvalenti/miniforge3/envs/Parcels_24/lib/python3.11/site-packages/xarray/core/dataset.py", line 2310, in to_netcdf
    return to_netcdf(  # type: ignore  # mypy cannot resolve the overloads:(
           ^^^^^^^^^^^^^^^^^^^^^^^^^^^^^^^^^^^^^^^^^^^^^^^^^^^^^^^^^^^^^^^^^
  File "/home/jvalenti/miniforge3/envs/Parcels_24/lib/python3.11/site-packages/xarray/backends/api.py", line 1298, in to_netcdf
    store = store_open(target, mode, format, group, **kwargs)
            ^^^^^^^^^^^^^^^^^^^^^^^^^^^^^^^^^^^^^^^^^^^^^^^^^
  File "/home/jvalenti/miniforge3/envs/Parcels_24/lib/python3.11/site-packages/xarray/backends/netCDF4_.py", line 400, in open
    return cls(manager, group=group, mode=mode, lock=lock, autoclose=autoclose)
           ^^^^^^^^^^^^^^^^^^^^^^^^^^^^^^^^^^^^^^^^^^^^^^^^^^^^^^^^^^^^^^^^^^^^
  File "/home/jvalenti/miniforge3/envs/Parcels_24/lib/python3.11/site-packages/xarray/backends/netCDF4_.py", line 347, in __init__
    self.format = self.ds.data_model
                  ^^^^^^^
  File "/home/jvalenti/miniforge3/envs/Parcels_24/lib/python3.11/site-packages/xarray/backends/netCDF4_.py", line 409, in ds
    return self._acquire()
           ^^^^^^^^^^^^^^^
  File "/home/jvalenti/miniforge3/envs/Parcels_24/lib/python3.11/site-packages/xarray/backends/netCDF4_.py", line 403, in _acquire
    with self._manager.acquire_context(needs_lock) as root:
  File "/home/jvalenti/miniforge3/envs/Parcels_24/lib/python3.11/contextlib.py", line 137, in __enter__
    return next(self.gen)
           ^^^^^^^^^^^^^^
  File "/home/jvalenti/miniforge3/envs/Parcels_24/lib/python3.11/site-packages/xarray/backends/file_manager.py", line 199, in acquire_context
    file, cached = self._acquire_with_cache_info(needs_lock)
                   ^^^^^^^^^^^^^^^^^^^^^^^^^^^^^^^^^^^^^^^^^
  File "/home/jvalenti/miniforge3/envs/Parcels_24/lib/python3.11/site-packages/xarray/backends/file_manager.py", line 217, in _acquire_with_cache_info
    file = self._opener(*self._args, **kwargs)
           ^^^^^^^^^^^^^^^^^^^^^^^^^^^^^^^^^^^
  File "src/netCDF4/_netCDF4.pyx", line 2469, in netCDF4._netCDF4.Dataset.__init__
  File "src/netCDF4/_netCDF4.pyx", line 2028, in netCDF4._netCDF4._ensure_nc_success
PermissionError: [Errno 13] Permission denied: '/home/jvalenti/projects/rrg-allen/jvalenti/restartruns/Parcels.nc'
Traceback (most recent call last):
  File "/home/jvalenti/miniforge3/envs/Parcels_24/lib/python3.11/site-packages/xarray/backends/file_manager.py", line 211, in _acquire_with_cache_info
    file = self._cache[self._key]
           ~~~~~~~~~~~^^^^^^^^^^^
  File "/home/jvalenti/miniforge3/envs/Parcels_24/lib/python3.11/site-packages/xarray/backends/lru_cache.py", line 56, in __getitem__
    value = self._cache[key]
            ~~~~~~~~~~~^^^^^
KeyError: [<class 'netCDF4._netCDF4.Dataset'>, ('/home/jvalenti/projects/rrg-allen/jvalenti/restartruns/Parcels.nc',), 'a', (('clobber', True), ('diskless', False), ('format', 'NETCDF4'), ('persist', False)), 'cc77a7cc-b55f-4ebf-9d87-6e93730859e1']

During handling of the above exception, another exception occurred:

Traceback (most recent call last):
  File "<frozen runpy>", line 198, in _run_module_as_main
  File "<frozen runpy>", line 88, in _run_code
  File "/home/jvalenti/MOAD/analysis-jose/Graham/Plastics_MCrestart.py", line 158, in <module>
    Restart_OP(config)
  File "/home/jvalenti/MOAD/analysis-jose/Graham/Plastics_MCrestart.py", line 143, in Restart_OP
    ds.to_netcdf('/home/jvalenti/projects/rrg-allen/jvalenti/restart'+names+'.nc')
  File "/home/jvalenti/miniforge3/envs/Parcels_24/lib/python3.11/site-packages/xarray/core/dataset.py", line 2310, in to_netcdf
    return to_netcdf(  # type: ignore  # mypy cannot resolve the overloads:(
           ^^^^^^^^^^^^^^^^^^^^^^^^^^^^^^^^^^^^^^^^^^^^^^^^^^^^^^^^^^^^^^^^^
  File "/home/jvalenti/miniforge3/envs/Parcels_24/lib/python3.11/site-packages/xarray/backends/api.py", line 1298, in to_netcdf
    store = store_open(target, mode, format, group, **kwargs)
            ^^^^^^^^^^^^^^^^^^^^^^^^^^^^^^^^^^^^^^^^^^^^^^^^^
  File "/home/jvalenti/miniforge3/envs/Parcels_24/lib/python3.11/site-packages/xarray/backends/netCDF4_.py", line 400, in open
    return cls(manager, group=group, mode=mode, lock=lock, autoclose=autoclose)
           ^^^^^^^^^^^^^^^^^^^^^^^^^^^^^^^^^^^^^^^^^^^^^^^^^^^^^^^^^^^^^^^^^^^^
  File "/home/jvalenti/miniforge3/envs/Parcels_24/lib/python3.11/site-packages/xarray/backends/netCDF4_.py", line 347, in __init__
    self.format = self.ds.data_model
                  ^^^^^^^
  File "/home/jvalenti/miniforge3/envs/Parcels_24/lib/python3.11/site-packages/xarray/backends/netCDF4_.py", line 409, in ds
    return self._acquire()
           ^^^^^^^^^^^^^^^
  File "/home/jvalenti/miniforge3/envs/Parcels_24/lib/python3.11/site-packages/xarray/backends/netCDF4_.py", line 403, in _acquire
    with self._manager.acquire_context(needs_lock) as root:
  File "/home/jvalenti/miniforge3/envs/Parcels_24/lib/python3.11/contextlib.py", line 137, in __enter__
    return next(self.gen)
           ^^^^^^^^^^^^^^
  File "/home/jvalenti/miniforge3/envs/Parcels_24/lib/python3.11/site-packages/xarray/backends/file_manager.py", line 199, in acquire_context
    file, cached = self._acquire_with_cache_info(needs_lock)
                   ^^^^^^^^^^^^^^^^^^^^^^^^^^^^^^^^^^^^^^^^^
  File "/home/jvalenti/miniforge3/envs/Parcels_24/lib/python3.11/site-packages/xarray/backends/file_manager.py", line 217, in _acquire_with_cache_info
    file = self._opener(*self._args, **kwargs)
           ^^^^^^^^^^^^^^^^^^^^^^^^^^^^^^^^^^^
  File "src/netCDF4/_netCDF4.pyx", line 2469, in netCDF4._netCDF4.Dataset.__init__
  File "src/netCDF4/_netCDF4.pyx", line 2028, in netCDF4._netCDF4._ensure_nc_success
PermissionError: [Errno 13] Permission denied: '/home/jvalenti/projects/rrg-allen/jvalenti/restartruns/Parcels.nc'
Traceback (most recent call last):
  File "/home/jvalenti/miniforge3/envs/Parcels_24/lib/python3.11/site-packages/xarray/backends/file_manager.py", line 211, in _acquire_with_cache_info
    file = self._cache[self._key]
           ~~~~~~~~~~~^^^^^^^^^^^
  File "/home/jvalenti/miniforge3/envs/Parcels_24/lib/python3.11/site-packages/xarray/backends/lru_cache.py", line 56, in __getitem__
    value = self._cache[key]
            ~~~~~~~~~~~^^^^^
KeyError: [<class 'netCDF4._netCDF4.Dataset'>, ('/home/jvalenti/projects/rrg-allen/jvalenti/restartruns/Parcels.nc',), 'a', (('clobber', True), ('diskless', False), ('format', 'NETCDF4'), ('persist', False)), '1f2e6933-56aa-415c-a8a9-ea8ae1983a2c']

During handling of the above exception, another exception occurred:

Traceback (most recent call last):
  File "<frozen runpy>", line 198, in _run_module_as_main
  File "<frozen runpy>", line 88, in _run_code
  File "/home/jvalenti/MOAD/analysis-jose/Graham/Plastics_MCrestart.py", line 158, in <module>
    Restart_OP(config)
  File "/home/jvalenti/MOAD/analysis-jose/Graham/Plastics_MCrestart.py", line 143, in Restart_OP
    ds.to_netcdf('/home/jvalenti/projects/rrg-allen/jvalenti/restart'+names+'.nc')
  File "/home/jvalenti/miniforge3/envs/Parcels_24/lib/python3.11/site-packages/xarray/core/dataset.py", line 2310, in to_netcdf
    return to_netcdf(  # type: ignore  # mypy cannot resolve the overloads:(
           ^^^^^^^^^^^^^^^^^^^^^^^^^^^^^^^^^^^^^^^^^^^^^^^^^^^^^^^^^^^^^^^^^
  File "/home/jvalenti/miniforge3/envs/Parcels_24/lib/python3.11/site-packages/xarray/backends/api.py", line 1298, in to_netcdf
    store = store_open(target, mode, format, group, **kwargs)
            ^^^^^^^^^^^^^^^^^^^^^^^^^^^^^^^^^^^^^^^^^^^^^^^^^
  File "/home/jvalenti/miniforge3/envs/Parcels_24/lib/python3.11/site-packages/xarray/backends/netCDF4_.py", line 400, in open
    return cls(manager, group=group, mode=mode, lock=lock, autoclose=autoclose)
           ^^^^^^^^^^^^^^^^^^^^^^^^^^^^^^^^^^^^^^^^^^^^^^^^^^^^^^^^^^^^^^^^^^^^
  File "/home/jvalenti/miniforge3/envs/Parcels_24/lib/python3.11/site-packages/xarray/backends/netCDF4_.py", line 347, in __init__
    self.format = self.ds.data_model
                  ^^^^^^^
  File "/home/jvalenti/miniforge3/envs/Parcels_24/lib/python3.11/site-packages/xarray/backends/netCDF4_.py", line 409, in ds
    return self._acquire()
           ^^^^^^^^^^^^^^^
  File "/home/jvalenti/miniforge3/envs/Parcels_24/lib/python3.11/site-packages/xarray/backends/netCDF4_.py", line 403, in _acquire
    with self._manager.acquire_context(needs_lock) as root:
  File "/home/jvalenti/miniforge3/envs/Parcels_24/lib/python3.11/contextlib.py", line 137, in __enter__
    return next(self.gen)
           ^^^^^^^^^^^^^^
  File "/home/jvalenti/miniforge3/envs/Parcels_24/lib/python3.11/site-packages/xarray/backends/file_manager.py", line 199, in acquire_context
    file, cached = self._acquire_with_cache_info(needs_lock)
                   ^^^^^^^^^^^^^^^^^^^^^^^^^^^^^^^^^^^^^^^^^
  File "/home/jvalenti/miniforge3/envs/Parcels_24/lib/python3.11/site-packages/xarray/backends/file_manager.py", line 217, in _acquire_with_cache_info
    file = self._opener(*self._args, **kwargs)
           ^^^^^^^^^^^^^^^^^^^^^^^^^^^^^^^^^^^
  File "src/netCDF4/_netCDF4.pyx", line 2469, in netCDF4._netCDF4.Dataset.__init__
  File "src/netCDF4/_netCDF4.pyx", line 2028, in netCDF4._netCDF4._ensure_nc_success
PermissionError: [Errno 13] Permission denied: '/home/jvalenti/projects/rrg-allen/jvalenti/restartruns/Parcels.nc'
Traceback (most recent call last):
  File "/home/jvalenti/miniforge3/envs/Parcels_24/lib/python3.11/site-packages/xarray/backends/file_manager.py", line 211, in _acquire_with_cache_info
    file = self._cache[self._key]
           ~~~~~~~~~~~^^^^^^^^^^^
  File "/home/jvalenti/miniforge3/envs/Parcels_24/lib/python3.11/site-packages/xarray/backends/lru_cache.py", line 56, in __getitem__
    value = self._cache[key]
            ~~~~~~~~~~~^^^^^
KeyError: [<class 'netCDF4._netCDF4.Dataset'>, ('/home/jvalenti/projects/rrg-allen/jvalenti/restartruns/Parcels.nc',), 'a', (('clobber', True), ('diskless', False), ('format', 'NETCDF4'), ('persist', False)), 'fde2c969-5a0c-4eff-86fa-6ec4827a9f20']

During handling of the above exception, another exception occurred:

Traceback (most recent call last):
  File "<frozen runpy>", line 198, in _run_module_as_main
  File "<frozen runpy>", line 88, in _run_code
  File "/home/jvalenti/MOAD/analysis-jose/Graham/Plastics_MCrestart.py", line 158, in <module>
    Restart_OP(config)
  File "/home/jvalenti/MOAD/analysis-jose/Graham/Plastics_MCrestart.py", line 143, in Restart_OP
    ds.to_netcdf('/home/jvalenti/projects/rrg-allen/jvalenti/restart'+names+'.nc')
  File "/home/jvalenti/miniforge3/envs/Parcels_24/lib/python3.11/site-packages/xarray/core/dataset.py", line 2310, in to_netcdf
    return to_netcdf(  # type: ignore  # mypy cannot resolve the overloads:(
           ^^^^^^^^^^^^^^^^^^^^^^^^^^^^^^^^^^^^^^^^^^^^^^^^^^^^^^^^^^^^^^^^^
  File "/home/jvalenti/miniforge3/envs/Parcels_24/lib/python3.11/site-packages/xarray/backends/api.py", line 1298, in to_netcdf
    store = store_open(target, mode, format, group, **kwargs)
            ^^^^^^^^^^^^^^^^^^^^^^^^^^^^^^^^^^^^^^^^^^^^^^^^^
  File "/home/jvalenti/miniforge3/envs/Parcels_24/lib/python3.11/site-packages/xarray/backends/netCDF4_.py", line 400, in open
    return cls(manager, group=group, mode=mode, lock=lock, autoclose=autoclose)
           ^^^^^^^^^^^^^^^^^^^^^^^^^^^^^^^^^^^^^^^^^^^^^^^^^^^^^^^^^^^^^^^^^^^^
  File "/home/jvalenti/miniforge3/envs/Parcels_24/lib/python3.11/site-packages/xarray/backends/netCDF4_.py", line 347, in __init__
    self.format = self.ds.data_model
                  ^^^^^^^
  File "/home/jvalenti/miniforge3/envs/Parcels_24/lib/python3.11/site-packages/xarray/backends/netCDF4_.py", line 409, in ds
    return self._acquire()
           ^^^^^^^^^^^^^^^
  File "/home/jvalenti/miniforge3/envs/Parcels_24/lib/python3.11/site-packages/xarray/backends/netCDF4_.py", line 403, in _acquire
    with self._manager.acquire_context(needs_lock) as root:
  File "/home/jvalenti/miniforge3/envs/Parcels_24/lib/python3.11/contextlib.py", line 137, in __enter__
    return next(self.gen)
           ^^^^^^^^^^^^^^
  File "/home/jvalenti/miniforge3/envs/Parcels_24/lib/python3.11/site-packages/xarray/backends/file_manager.py", line 199, in acquire_context
    file, cached = self._acquire_with_cache_info(needs_lock)
                   ^^^^^^^^^^^^^^^^^^^^^^^^^^^^^^^^^^^^^^^^^
  File "/home/jvalenti/miniforge3/envs/Parcels_24/lib/python3.11/site-packages/xarray/backends/file_manager.py", line 217, in _acquire_with_cache_info
    file = self._opener(*self._args, **kwargs)
           ^^^^^^^^^^^^^^^^^^^^^^^^^^^^^^^^^^^
  File "src/netCDF4/_netCDF4.pyx", line 2469, in netCDF4._netCDF4.Dataset.__init__
  File "src/netCDF4/_netCDF4.pyx", line 2028, in netCDF4._netCDF4._ensure_nc_success
PermissionError: [Errno 13] Permission denied: '/home/jvalenti/projects/rrg-allen/jvalenti/restartruns/Parcels.nc'
Traceback (most recent call last):
  File "/home/jvalenti/miniforge3/envs/Parcels_24/lib/python3.11/site-packages/xarray/backends/file_manager.py", line 211, in _acquire_with_cache_info
    file = self._cache[self._key]
           ~~~~~~~~~~~^^^^^^^^^^^
  File "/home/jvalenti/miniforge3/envs/Parcels_24/lib/python3.11/site-packages/xarray/backends/lru_cache.py", line 56, in __getitem__
    value = self._cache[key]
            ~~~~~~~~~~~^^^^^
KeyError: [<class 'netCDF4._netCDF4.Dataset'>, ('/home/jvalenti/projects/rrg-allen/jvalenti/restartruns/Parcels.nc',), 'a', (('clobber', True), ('diskless', False), ('format', 'NETCDF4'), ('persist', False)), '11da8191-4ebf-4463-bd83-5720bea24656']

During handling of the above exception, another exception occurred:

Traceback (most recent call last):
  File "<frozen runpy>", line 198, in _run_module_as_main
  File "<frozen runpy>", line 88, in _run_code
  File "/home/jvalenti/MOAD/analysis-jose/Graham/Plastics_MCrestart.py", line 158, in <module>
    Restart_OP(config)
  File "/home/jvalenti/MOAD/analysis-jose/Graham/Plastics_MCrestart.py", line 143, in Restart_OP
    ds.to_netcdf('/home/jvalenti/projects/rrg-allen/jvalenti/restart'+names+'.nc')
  File "/home/jvalenti/miniforge3/envs/Parcels_24/lib/python3.11/site-packages/xarray/core/dataset.py", line 2310, in to_netcdf
    return to_netcdf(  # type: ignore  # mypy cannot resolve the overloads:(
           ^^^^^^^^^^^^^^^^^^^^^^^^^^^^^^^^^^^^^^^^^^^^^^^^^^^^^^^^^^^^^^^^^
  File "/home/jvalenti/miniforge3/envs/Parcels_24/lib/python3.11/site-packages/xarray/backends/api.py", line 1298, in to_netcdf
    store = store_open(target, mode, format, group, **kwargs)
            ^^^^^^^^^^^^^^^^^^^^^^^^^^^^^^^^^^^^^^^^^^^^^^^^^
  File "/home/jvalenti/miniforge3/envs/Parcels_24/lib/python3.11/site-packages/xarray/backends/netCDF4_.py", line 400, in open
    return cls(manager, group=group, mode=mode, lock=lock, autoclose=autoclose)
           ^^^^^^^^^^^^^^^^^^^^^^^^^^^^^^^^^^^^^^^^^^^^^^^^^^^^^^^^^^^^^^^^^^^^
  File "/home/jvalenti/miniforge3/envs/Parcels_24/lib/python3.11/site-packages/xarray/backends/netCDF4_.py", line 347, in __init__
    self.format = self.ds.data_model
                  ^^^^^^^
  File "/home/jvalenti/miniforge3/envs/Parcels_24/lib/python3.11/site-packages/xarray/backends/netCDF4_.py", line 409, in ds
    return self._acquire()
           ^^^^^^^^^^^^^^^
  File "/home/jvalenti/miniforge3/envs/Parcels_24/lib/python3.11/site-packages/xarray/backends/netCDF4_.py", line 403, in _acquire
    with self._manager.acquire_context(needs_lock) as root:
  File "/home/jvalenti/miniforge3/envs/Parcels_24/lib/python3.11/contextlib.py", line 137, in __enter__
    return next(self.gen)
           ^^^^^^^^^^^^^^
  File "/home/jvalenti/miniforge3/envs/Parcels_24/lib/python3.11/site-packages/xarray/backends/file_manager.py", line 199, in acquire_context
    file, cached = self._acquire_with_cache_info(needs_lock)
                   ^^^^^^^^^^^^^^^^^^^^^^^^^^^^^^^^^^^^^^^^^
  File "/home/jvalenti/miniforge3/envs/Parcels_24/lib/python3.11/site-packages/xarray/backends/file_manager.py", line 217, in _acquire_with_cache_info
    file = self._opener(*self._args, **kwargs)
           ^^^^^^^^^^^^^^^^^^^^^^^^^^^^^^^^^^^
  File "src/netCDF4/_netCDF4.pyx", line 2469, in netCDF4._netCDF4.Dataset.__init__
  File "src/netCDF4/_netCDF4.pyx", line 2028, in netCDF4._netCDF4._ensure_nc_success
PermissionError: [Errno 13] Permission denied: '/home/jvalenti/projects/rrg-allen/jvalenti/restartruns/Parcels.nc'
Traceback (most recent call last):
  File "/home/jvalenti/miniforge3/envs/Parcels_24/lib/python3.11/site-packages/xarray/backends/file_manager.py", line 211, in _acquire_with_cache_info
    file = self._cache[self._key]
           ~~~~~~~~~~~^^^^^^^^^^^
  File "/home/jvalenti/miniforge3/envs/Parcels_24/lib/python3.11/site-packages/xarray/backends/lru_cache.py", line 56, in __getitem__
    value = self._cache[key]
            ~~~~~~~~~~~^^^^^
KeyError: [<class 'netCDF4._netCDF4.Dataset'>, ('/home/jvalenti/projects/rrg-allen/jvalenti/restartruns/Parcels.nc',), 'a', (('clobber', True), ('diskless', False), ('format', 'NETCDF4'), ('persist', False)), '3a9a7be0-81f1-4491-a867-706a5554bc09']

During handling of the above exception, another exception occurred:

Traceback (most recent call last):
  File "<frozen runpy>", line 198, in _run_module_as_main
  File "<frozen runpy>", line 88, in _run_code
  File "/home/jvalenti/MOAD/analysis-jose/Graham/Plastics_MCrestart.py", line 158, in <module>
    Restart_OP(config)
  File "/home/jvalenti/MOAD/analysis-jose/Graham/Plastics_MCrestart.py", line 143, in Restart_OP
    ds.to_netcdf('/home/jvalenti/projects/rrg-allen/jvalenti/restart'+names+'.nc')
  File "/home/jvalenti/miniforge3/envs/Parcels_24/lib/python3.11/site-packages/xarray/core/dataset.py", line 2310, in to_netcdf
    return to_netcdf(  # type: ignore  # mypy cannot resolve the overloads:(
           ^^^^^^^^^^^^^^^^^^^^^^^^^^^^^^^^^^^^^^^^^^^^^^^^^^^^^^^^^^^^^^^^^
  File "/home/jvalenti/miniforge3/envs/Parcels_24/lib/python3.11/site-packages/xarray/backends/api.py", line 1298, in to_netcdf
    store = store_open(target, mode, format, group, **kwargs)
            ^^^^^^^^^^^^^^^^^^^^^^^^^^^^^^^^^^^^^^^^^^^^^^^^^
  File "/home/jvalenti/miniforge3/envs/Parcels_24/lib/python3.11/site-packages/xarray/backends/netCDF4_.py", line 400, in open
    return cls(manager, group=group, mode=mode, lock=lock, autoclose=autoclose)
           ^^^^^^^^^^^^^^^^^^^^^^^^^^^^^^^^^^^^^^^^^^^^^^^^^^^^^^^^^^^^^^^^^^^^
  File "/home/jvalenti/miniforge3/envs/Parcels_24/lib/python3.11/site-packages/xarray/backends/netCDF4_.py", line 347, in __init__
    self.format = self.ds.data_model
                  ^^^^^^^
  File "/home/jvalenti/miniforge3/envs/Parcels_24/lib/python3.11/site-packages/xarray/backends/netCDF4_.py", line 409, in ds
    return self._acquire()
           ^^^^^^^^^^^^^^^
  File "/home/jvalenti/miniforge3/envs/Parcels_24/lib/python3.11/site-packages/xarray/backends/netCDF4_.py", line 403, in _acquire
    with self._manager.acquire_context(needs_lock) as root:
  File "/home/jvalenti/miniforge3/envs/Parcels_24/lib/python3.11/contextlib.py", line 137, in __enter__
    return next(self.gen)
           ^^^^^^^^^^^^^^
  File "/home/jvalenti/miniforge3/envs/Parcels_24/lib/python3.11/site-packages/xarray/backends/file_manager.py", line 199, in acquire_context
    file, cached = self._acquire_with_cache_info(needs_lock)
                   ^^^^^^^^^^^^^^^^^^^^^^^^^^^^^^^^^^^^^^^^^
  File "/home/jvalenti/miniforge3/envs/Parcels_24/lib/python3.11/site-packages/xarray/backends/file_manager.py", line 217, in _acquire_with_cache_info
    file = self._opener(*self._args, **kwargs)
           ^^^^^^^^^^^^^^^^^^^^^^^^^^^^^^^^^^^
  File "src/netCDF4/_netCDF4.pyx", line 2469, in netCDF4._netCDF4.Dataset.__init__
  File "src/netCDF4/_netCDF4.pyx", line 2028, in netCDF4._netCDF4._ensure_nc_success
PermissionError: [Errno 13] Permission denied: '/home/jvalenti/projects/rrg-allen/jvalenti/restartruns/Parcels.nc'
Traceback (most recent call last):
  File "/home/jvalenti/miniforge3/envs/Parcels_24/lib/python3.11/site-packages/xarray/backends/file_manager.py", line 211, in _acquire_with_cache_info
    file = self._cache[self._key]
           ~~~~~~~~~~~^^^^^^^^^^^
  File "/home/jvalenti/miniforge3/envs/Parcels_24/lib/python3.11/site-packages/xarray/backends/lru_cache.py", line 56, in __getitem__
    value = self._cache[key]
            ~~~~~~~~~~~^^^^^
KeyError: [<class 'netCDF4._netCDF4.Dataset'>, ('/home/jvalenti/projects/rrg-allen/jvalenti/restartruns/Parcels.nc',), 'a', (('clobber', True), ('diskless', False), ('format', 'NETCDF4'), ('persist', False)), '45dbb49c-ba87-44d9-919a-e397bea39fcb']

During handling of the above exception, another exception occurred:

Traceback (most recent call last):
  File "<frozen runpy>", line 198, in _run_module_as_main
  File "<frozen runpy>", line 88, in _run_code
  File "/home/jvalenti/MOAD/analysis-jose/Graham/Plastics_MCrestart.py", line 158, in <module>
    Restart_OP(config)
  File "/home/jvalenti/MOAD/analysis-jose/Graham/Plastics_MCrestart.py", line 143, in Restart_OP
    ds.to_netcdf('/home/jvalenti/projects/rrg-allen/jvalenti/restart'+names+'.nc')
  File "/home/jvalenti/miniforge3/envs/Parcels_24/lib/python3.11/site-packages/xarray/core/dataset.py", line 2310, in to_netcdf
    return to_netcdf(  # type: ignore  # mypy cannot resolve the overloads:(
           ^^^^^^^^^^^^^^^^^^^^^^^^^^^^^^^^^^^^^^^^^^^^^^^^^^^^^^^^^^^^^^^^^
  File "/home/jvalenti/miniforge3/envs/Parcels_24/lib/python3.11/site-packages/xarray/backends/api.py", line 1298, in to_netcdf
    store = store_open(target, mode, format, group, **kwargs)
            ^^^^^^^^^^^^^^^^^^^^^^^^^^^^^^^^^^^^^^^^^^^^^^^^^
  File "/home/jvalenti/miniforge3/envs/Parcels_24/lib/python3.11/site-packages/xarray/backends/netCDF4_.py", line 400, in open
    return cls(manager, group=group, mode=mode, lock=lock, autoclose=autoclose)
           ^^^^^^^^^^^^^^^^^^^^^^^^^^^^^^^^^^^^^^^^^^^^^^^^^^^^^^^^^^^^^^^^^^^^
  File "/home/jvalenti/miniforge3/envs/Parcels_24/lib/python3.11/site-packages/xarray/backends/netCDF4_.py", line 347, in __init__
    self.format = self.ds.data_model
                  ^^^^^^^
  File "/home/jvalenti/miniforge3/envs/Parcels_24/lib/python3.11/site-packages/xarray/backends/netCDF4_.py", line 409, in ds
    return self._acquire()
           ^^^^^^^^^^^^^^^
  File "/home/jvalenti/miniforge3/envs/Parcels_24/lib/python3.11/site-packages/xarray/backends/netCDF4_.py", line 403, in _acquire
    with self._manager.acquire_context(needs_lock) as root:
  File "/home/jvalenti/miniforge3/envs/Parcels_24/lib/python3.11/contextlib.py", line 137, in __enter__
    return next(self.gen)
           ^^^^^^^^^^^^^^
  File "/home/jvalenti/miniforge3/envs/Parcels_24/lib/python3.11/site-packages/xarray/backends/file_manager.py", line 199, in acquire_context
    file, cached = self._acquire_with_cache_info(needs_lock)
                   ^^^^^^^^^^^^^^^^^^^^^^^^^^^^^^^^^^^^^^^^^
  File "/home/jvalenti/miniforge3/envs/Parcels_24/lib/python3.11/site-packages/xarray/backends/file_manager.py", line 217, in _acquire_with_cache_info
    file = self._opener(*self._args, **kwargs)
           ^^^^^^^^^^^^^^^^^^^^^^^^^^^^^^^^^^^
  File "src/netCDF4/_netCDF4.pyx", line 2469, in netCDF4._netCDF4.Dataset.__init__
  File "src/netCDF4/_netCDF4.pyx", line 2028, in netCDF4._netCDF4._ensure_nc_success
PermissionError: [Errno 13] Permission denied: '/home/jvalenti/projects/rrg-allen/jvalenti/restartruns/Parcels.nc'
Traceback (most recent call last):
  File "/home/jvalenti/miniforge3/envs/Parcels_24/lib/python3.11/site-packages/xarray/backends/file_manager.py", line 211, in _acquire_with_cache_info
    file = self._cache[self._key]
           ~~~~~~~~~~~^^^^^^^^^^^
  File "/home/jvalenti/miniforge3/envs/Parcels_24/lib/python3.11/site-packages/xarray/backends/lru_cache.py", line 56, in __getitem__
    value = self._cache[key]
            ~~~~~~~~~~~^^^^^
KeyError: [<class 'netCDF4._netCDF4.Dataset'>, ('/home/jvalenti/projects/rrg-allen/jvalenti/restartruns/Parcels.nc',), 'a', (('clobber', True), ('diskless', False), ('format', 'NETCDF4'), ('persist', False)), '66cf428a-003d-4e53-b943-4fd1f99283bf']

During handling of the above exception, another exception occurred:

Traceback (most recent call last):
  File "<frozen runpy>", line 198, in _run_module_as_main
  File "<frozen runpy>", line 88, in _run_code
  File "/home/jvalenti/MOAD/analysis-jose/Graham/Plastics_MCrestart.py", line 158, in <module>
    Restart_OP(config)
  File "/home/jvalenti/MOAD/analysis-jose/Graham/Plastics_MCrestart.py", line 143, in Restart_OP
    ds.to_netcdf('/home/jvalenti/projects/rrg-allen/jvalenti/restart'+names+'.nc')
  File "/home/jvalenti/miniforge3/envs/Parcels_24/lib/python3.11/site-packages/xarray/core/dataset.py", line 2310, in to_netcdf
    return to_netcdf(  # type: ignore  # mypy cannot resolve the overloads:(
           ^^^^^^^^^^^^^^^^^^^^^^^^^^^^^^^^^^^^^^^^^^^^^^^^^^^^^^^^^^^^^^^^^
  File "/home/jvalenti/miniforge3/envs/Parcels_24/lib/python3.11/site-packages/xarray/backends/api.py", line 1298, in to_netcdf
    store = store_open(target, mode, format, group, **kwargs)
            ^^^^^^^^^^^^^^^^^^^^^^^^^^^^^^^^^^^^^^^^^^^^^^^^^
  File "/home/jvalenti/miniforge3/envs/Parcels_24/lib/python3.11/site-packages/xarray/backends/netCDF4_.py", line 400, in open
    return cls(manager, group=group, mode=mode, lock=lock, autoclose=autoclose)
           ^^^^^^^^^^^^^^^^^^^^^^^^^^^^^^^^^^^^^^^^^^^^^^^^^^^^^^^^^^^^^^^^^^^^
  File "/home/jvalenti/miniforge3/envs/Parcels_24/lib/python3.11/site-packages/xarray/backends/netCDF4_.py", line 347, in __init__
    self.format = self.ds.data_model
                  ^^^^^^^
  File "/home/jvalenti/miniforge3/envs/Parcels_24/lib/python3.11/site-packages/xarray/backends/netCDF4_.py", line 409, in ds
    return self._acquire()
           ^^^^^^^^^^^^^^^
  File "/home/jvalenti/miniforge3/envs/Parcels_24/lib/python3.11/site-packages/xarray/backends/netCDF4_.py", line 403, in _acquire
    with self._manager.acquire_context(needs_lock) as root:
  File "/home/jvalenti/miniforge3/envs/Parcels_24/lib/python3.11/contextlib.py", line 137, in __enter__
    return next(self.gen)
           ^^^^^^^^^^^^^^
  File "/home/jvalenti/miniforge3/envs/Parcels_24/lib/python3.11/site-packages/xarray/backends/file_manager.py", line 199, in acquire_context
    file, cached = self._acquire_with_cache_info(needs_lock)
                   ^^^^^^^^^^^^^^^^^^^^^^^^^^^^^^^^^^^^^^^^^
  File "/home/jvalenti/miniforge3/envs/Parcels_24/lib/python3.11/site-packages/xarray/backends/file_manager.py", line 217, in _acquire_with_cache_info
    file = self._opener(*self._args, **kwargs)
           ^^^^^^^^^^^^^^^^^^^^^^^^^^^^^^^^^^^
  File "src/netCDF4/_netCDF4.pyx", line 2469, in netCDF4._netCDF4.Dataset.__init__
  File "src/netCDF4/_netCDF4.pyx", line 2028, in netCDF4._netCDF4._ensure_nc_success
PermissionError: [Errno 13] Permission denied: '/home/jvalenti/projects/rrg-allen/jvalenti/restartruns/Parcels.nc'
Traceback (most recent call last):
  File "/home/jvalenti/miniforge3/envs/Parcels_24/lib/python3.11/site-packages/xarray/backends/file_manager.py", line 211, in _acquire_with_cache_info
    file = self._cache[self._key]
           ~~~~~~~~~~~^^^^^^^^^^^
  File "/home/jvalenti/miniforge3/envs/Parcels_24/lib/python3.11/site-packages/xarray/backends/lru_cache.py", line 56, in __getitem__
    value = self._cache[key]
            ~~~~~~~~~~~^^^^^
KeyError: [<class 'netCDF4._netCDF4.Dataset'>, ('/home/jvalenti/projects/rrg-allen/jvalenti/restartruns/Parcels.nc',), 'a', (('clobber', True), ('diskless', False), ('format', 'NETCDF4'), ('persist', False)), 'a183f0dd-95e1-4aa9-a742-01eb2de0e846']

During handling of the above exception, another exception occurred:

Traceback (most recent call last):
  File "<frozen runpy>", line 198, in _run_module_as_main
  File "<frozen runpy>", line 88, in _run_code
  File "/home/jvalenti/MOAD/analysis-jose/Graham/Plastics_MCrestart.py", line 158, in <module>
    Restart_OP(config)
  File "/home/jvalenti/MOAD/analysis-jose/Graham/Plastics_MCrestart.py", line 143, in Restart_OP
    ds.to_netcdf('/home/jvalenti/projects/rrg-allen/jvalenti/restart'+names+'.nc')
  File "/home/jvalenti/miniforge3/envs/Parcels_24/lib/python3.11/site-packages/xarray/core/dataset.py", line 2310, in to_netcdf
    return to_netcdf(  # type: ignore  # mypy cannot resolve the overloads:(
           ^^^^^^^^^^^^^^^^^^^^^^^^^^^^^^^^^^^^^^^^^^^^^^^^^^^^^^^^^^^^^^^^^
  File "/home/jvalenti/miniforge3/envs/Parcels_24/lib/python3.11/site-packages/xarray/backends/api.py", line 1298, in to_netcdf
    store = store_open(target, mode, format, group, **kwargs)
            ^^^^^^^^^^^^^^^^^^^^^^^^^^^^^^^^^^^^^^^^^^^^^^^^^
  File "/home/jvalenti/miniforge3/envs/Parcels_24/lib/python3.11/site-packages/xarray/backends/netCDF4_.py", line 400, in open
    return cls(manager, group=group, mode=mode, lock=lock, autoclose=autoclose)
           ^^^^^^^^^^^^^^^^^^^^^^^^^^^^^^^^^^^^^^^^^^^^^^^^^^^^^^^^^^^^^^^^^^^^
  File "/home/jvalenti/miniforge3/envs/Parcels_24/lib/python3.11/site-packages/xarray/backends/netCDF4_.py", line 347, in __init__
    self.format = self.ds.data_model
                  ^^^^^^^
  File "/home/jvalenti/miniforge3/envs/Parcels_24/lib/python3.11/site-packages/xarray/backends/netCDF4_.py", line 409, in ds
    return self._acquire()
           ^^^^^^^^^^^^^^^
  File "/home/jvalenti/miniforge3/envs/Parcels_24/lib/python3.11/site-packages/xarray/backends/netCDF4_.py", line 403, in _acquire
    with self._manager.acquire_context(needs_lock) as root:
  File "/home/jvalenti/miniforge3/envs/Parcels_24/lib/python3.11/contextlib.py", line 137, in __enter__
    return next(self.gen)
           ^^^^^^^^^^^^^^
  File "/home/jvalenti/miniforge3/envs/Parcels_24/lib/python3.11/site-packages/xarray/backends/file_manager.py", line 199, in acquire_context
    file, cached = self._acquire_with_cache_info(needs_lock)
                   ^^^^^^^^^^^^^^^^^^^^^^^^^^^^^^^^^^^^^^^^^
  File "/home/jvalenti/miniforge3/envs/Parcels_24/lib/python3.11/site-packages/xarray/backends/file_manager.py", line 217, in _acquire_with_cache_info
    file = self._opener(*self._args, **kwargs)
           ^^^^^^^^^^^^^^^^^^^^^^^^^^^^^^^^^^^
  File "src/netCDF4/_netCDF4.pyx", line 2469, in netCDF4._netCDF4.Dataset.__init__
  File "src/netCDF4/_netCDF4.pyx", line 2028, in netCDF4._netCDF4._ensure_nc_success
PermissionError: [Errno 13] Permission denied: '/home/jvalenti/projects/rrg-allen/jvalenti/restartruns/Parcels.nc'
Traceback (most recent call last):
  File "/home/jvalenti/miniforge3/envs/Parcels_24/lib/python3.11/site-packages/xarray/backends/file_manager.py", line 211, in _acquire_with_cache_info
    file = self._cache[self._key]
           ~~~~~~~~~~~^^^^^^^^^^^
  File "/home/jvalenti/miniforge3/envs/Parcels_24/lib/python3.11/site-packages/xarray/backends/lru_cache.py", line 56, in __getitem__
    value = self._cache[key]
            ~~~~~~~~~~~^^^^^
KeyError: [<class 'netCDF4._netCDF4.Dataset'>, ('/home/jvalenti/projects/rrg-allen/jvalenti/restartruns/Parcels.nc',), 'a', (('clobber', True), ('diskless', False), ('format', 'NETCDF4'), ('persist', False)), '23b3b47f-683b-448a-b4e7-cd09bcd77629']

During handling of the above exception, another exception occurred:

Traceback (most recent call last):
  File "<frozen runpy>", line 198, in _run_module_as_main
  File "<frozen runpy>", line 88, in _run_code
  File "/home/jvalenti/MOAD/analysis-jose/Graham/Plastics_MCrestart.py", line 158, in <module>
    Restart_OP(config)
  File "/home/jvalenti/MOAD/analysis-jose/Graham/Plastics_MCrestart.py", line 143, in Restart_OP
    ds.to_netcdf('/home/jvalenti/projects/rrg-allen/jvalenti/restart'+names+'.nc')
  File "/home/jvalenti/miniforge3/envs/Parcels_24/lib/python3.11/site-packages/xarray/core/dataset.py", line 2310, in to_netcdf
    return to_netcdf(  # type: ignore  # mypy cannot resolve the overloads:(
           ^^^^^^^^^^^^^^^^^^^^^^^^^^^^^^^^^^^^^^^^^^^^^^^^^^^^^^^^^^^^^^^^^
  File "/home/jvalenti/miniforge3/envs/Parcels_24/lib/python3.11/site-packages/xarray/backends/api.py", line 1298, in to_netcdf
    store = store_open(target, mode, format, group, **kwargs)
            ^^^^^^^^^^^^^^^^^^^^^^^^^^^^^^^^^^^^^^^^^^^^^^^^^
  File "/home/jvalenti/miniforge3/envs/Parcels_24/lib/python3.11/site-packages/xarray/backends/netCDF4_.py", line 400, in open
    return cls(manager, group=group, mode=mode, lock=lock, autoclose=autoclose)
           ^^^^^^^^^^^^^^^^^^^^^^^^^^^^^^^^^^^^^^^^^^^^^^^^^^^^^^^^^^^^^^^^^^^^
  File "/home/jvalenti/miniforge3/envs/Parcels_24/lib/python3.11/site-packages/xarray/backends/netCDF4_.py", line 347, in __init__
    self.format = self.ds.data_model
                  ^^^^^^^
  File "/home/jvalenti/miniforge3/envs/Parcels_24/lib/python3.11/site-packages/xarray/backends/netCDF4_.py", line 409, in ds
    return self._acquire()
           ^^^^^^^^^^^^^^^
  File "/home/jvalenti/miniforge3/envs/Parcels_24/lib/python3.11/site-packages/xarray/backends/netCDF4_.py", line 403, in _acquire
    with self._manager.acquire_context(needs_lock) as root:
  File "/home/jvalenti/miniforge3/envs/Parcels_24/lib/python3.11/contextlib.py", line 137, in __enter__
    return next(self.gen)
           ^^^^^^^^^^^^^^
  File "/home/jvalenti/miniforge3/envs/Parcels_24/lib/python3.11/site-packages/xarray/backends/file_manager.py", line 199, in acquire_context
    file, cached = self._acquire_with_cache_info(needs_lock)
                   ^^^^^^^^^^^^^^^^^^^^^^^^^^^^^^^^^^^^^^^^^
  File "/home/jvalenti/miniforge3/envs/Parcels_24/lib/python3.11/site-packages/xarray/backends/file_manager.py", line 217, in _acquire_with_cache_info
    file = self._opener(*self._args, **kwargs)
           ^^^^^^^^^^^^^^^^^^^^^^^^^^^^^^^^^^^
  File "src/netCDF4/_netCDF4.pyx", line 2469, in netCDF4._netCDF4.Dataset.__init__
  File "src/netCDF4/_netCDF4.pyx", line 2028, in netCDF4._netCDF4._ensure_nc_success
PermissionError: [Errno 13] Permission denied: '/home/jvalenti/projects/rrg-allen/jvalenti/restartruns/Parcels.nc'
Traceback (most recent call last):
  File "/home/jvalenti/miniforge3/envs/Parcels_24/lib/python3.11/site-packages/xarray/backends/file_manager.py", line 211, in _acquire_with_cache_info
    file = self._cache[self._key]
           ~~~~~~~~~~~^^^^^^^^^^^
  File "/home/jvalenti/miniforge3/envs/Parcels_24/lib/python3.11/site-packages/xarray/backends/lru_cache.py", line 56, in __getitem__
    value = self._cache[key]
            ~~~~~~~~~~~^^^^^
KeyError: [<class 'netCDF4._netCDF4.Dataset'>, ('/home/jvalenti/projects/rrg-allen/jvalenti/restartruns/Parcels.nc',), 'a', (('clobber', True), ('diskless', False), ('format', 'NETCDF4'), ('persist', False)), '297d373d-4ee7-4771-bc67-fe2b6c38cdb7']

During handling of the above exception, another exception occurred:

Traceback (most recent call last):
  File "<frozen runpy>", line 198, in _run_module_as_main
  File "<frozen runpy>", line 88, in _run_code
  File "/home/jvalenti/MOAD/analysis-jose/Graham/Plastics_MCrestart.py", line 158, in <module>
    Restart_OP(config)
  File "/home/jvalenti/MOAD/analysis-jose/Graham/Plastics_MCrestart.py", line 143, in Restart_OP
    ds.to_netcdf('/home/jvalenti/projects/rrg-allen/jvalenti/restart'+names+'.nc')
  File "/home/jvalenti/miniforge3/envs/Parcels_24/lib/python3.11/site-packages/xarray/core/dataset.py", line 2310, in to_netcdf
    return to_netcdf(  # type: ignore  # mypy cannot resolve the overloads:(
           ^^^^^^^^^^^^^^^^^^^^^^^^^^^^^^^^^^^^^^^^^^^^^^^^^^^^^^^^^^^^^^^^^
  File "/home/jvalenti/miniforge3/envs/Parcels_24/lib/python3.11/site-packages/xarray/backends/api.py", line 1298, in to_netcdf
    store = store_open(target, mode, format, group, **kwargs)
            ^^^^^^^^^^^^^^^^^^^^^^^^^^^^^^^^^^^^^^^^^^^^^^^^^
  File "/home/jvalenti/miniforge3/envs/Parcels_24/lib/python3.11/site-packages/xarray/backends/netCDF4_.py", line 400, in open
    return cls(manager, group=group, mode=mode, lock=lock, autoclose=autoclose)
           ^^^^^^^^^^^^^^^^^^^^^^^^^^^^^^^^^^^^^^^^^^^^^^^^^^^^^^^^^^^^^^^^^^^^
  File "/home/jvalenti/miniforge3/envs/Parcels_24/lib/python3.11/site-packages/xarray/backends/netCDF4_.py", line 347, in __init__
    self.format = self.ds.data_model
                  ^^^^^^^
  File "/home/jvalenti/miniforge3/envs/Parcels_24/lib/python3.11/site-packages/xarray/backends/netCDF4_.py", line 409, in ds
    return self._acquire()
           ^^^^^^^^^^^^^^^
  File "/home/jvalenti/miniforge3/envs/Parcels_24/lib/python3.11/site-packages/xarray/backends/netCDF4_.py", line 403, in _acquire
    with self._manager.acquire_context(needs_lock) as root:
  File "/home/jvalenti/miniforge3/envs/Parcels_24/lib/python3.11/contextlib.py", line 137, in __enter__
    return next(self.gen)
           ^^^^^^^^^^^^^^
  File "/home/jvalenti/miniforge3/envs/Parcels_24/lib/python3.11/site-packages/xarray/backends/file_manager.py", line 199, in acquire_context
    file, cached = self._acquire_with_cache_info(needs_lock)
                   ^^^^^^^^^^^^^^^^^^^^^^^^^^^^^^^^^^^^^^^^^
  File "/home/jvalenti/miniforge3/envs/Parcels_24/lib/python3.11/site-packages/xarray/backends/file_manager.py", line 217, in _acquire_with_cache_info
    file = self._opener(*self._args, **kwargs)
           ^^^^^^^^^^^^^^^^^^^^^^^^^^^^^^^^^^^
  File "src/netCDF4/_netCDF4.pyx", line 2469, in netCDF4._netCDF4.Dataset.__init__
  File "src/netCDF4/_netCDF4.pyx", line 2028, in netCDF4._netCDF4._ensure_nc_success
PermissionError: [Errno 13] Permission denied: '/home/jvalenti/projects/rrg-allen/jvalenti/restartruns/Parcels.nc'
Traceback (most recent call last):
  File "/home/jvalenti/miniforge3/envs/Parcels_24/lib/python3.11/site-packages/xarray/backends/file_manager.py", line 211, in _acquire_with_cache_info
    file = self._cache[self._key]
           ~~~~~~~~~~~^^^^^^^^^^^
  File "/home/jvalenti/miniforge3/envs/Parcels_24/lib/python3.11/site-packages/xarray/backends/lru_cache.py", line 56, in __getitem__
    value = self._cache[key]
            ~~~~~~~~~~~^^^^^
KeyError: [<class 'netCDF4._netCDF4.Dataset'>, ('/home/jvalenti/projects/rrg-allen/jvalenti/restartruns/Parcels.nc',), 'a', (('clobber', True), ('diskless', False), ('format', 'NETCDF4'), ('persist', False)), '58ba7f10-86d6-444c-ac61-b7d3267f3b3c']

During handling of the above exception, another exception occurred:

Traceback (most recent call last):
  File "<frozen runpy>", line 198, in _run_module_as_main
  File "<frozen runpy>", line 88, in _run_code
  File "/home/jvalenti/MOAD/analysis-jose/Graham/Plastics_MCrestart.py", line 158, in <module>
    Restart_OP(config)
  File "/home/jvalenti/MOAD/analysis-jose/Graham/Plastics_MCrestart.py", line 143, in Restart_OP
    ds.to_netcdf('/home/jvalenti/projects/rrg-allen/jvalenti/restart'+names+'.nc')
  File "/home/jvalenti/miniforge3/envs/Parcels_24/lib/python3.11/site-packages/xarray/core/dataset.py", line 2310, in to_netcdf
    return to_netcdf(  # type: ignore  # mypy cannot resolve the overloads:(
           ^^^^^^^^^^^^^^^^^^^^^^^^^^^^^^^^^^^^^^^^^^^^^^^^^^^^^^^^^^^^^^^^^
  File "/home/jvalenti/miniforge3/envs/Parcels_24/lib/python3.11/site-packages/xarray/backends/api.py", line 1298, in to_netcdf
    store = store_open(target, mode, format, group, **kwargs)
            ^^^^^^^^^^^^^^^^^^^^^^^^^^^^^^^^^^^^^^^^^^^^^^^^^
  File "/home/jvalenti/miniforge3/envs/Parcels_24/lib/python3.11/site-packages/xarray/backends/netCDF4_.py", line 400, in open
    return cls(manager, group=group, mode=mode, lock=lock, autoclose=autoclose)
           ^^^^^^^^^^^^^^^^^^^^^^^^^^^^^^^^^^^^^^^^^^^^^^^^^^^^^^^^^^^^^^^^^^^^
  File "/home/jvalenti/miniforge3/envs/Parcels_24/lib/python3.11/site-packages/xarray/backends/netCDF4_.py", line 347, in __init__
    self.format = self.ds.data_model
                  ^^^^^^^
  File "/home/jvalenti/miniforge3/envs/Parcels_24/lib/python3.11/site-packages/xarray/backends/netCDF4_.py", line 409, in ds
    return self._acquire()
           ^^^^^^^^^^^^^^^
  File "/home/jvalenti/miniforge3/envs/Parcels_24/lib/python3.11/site-packages/xarray/backends/netCDF4_.py", line 403, in _acquire
    with self._manager.acquire_context(needs_lock) as root:
  File "/home/jvalenti/miniforge3/envs/Parcels_24/lib/python3.11/contextlib.py", line 137, in __enter__
    return next(self.gen)
           ^^^^^^^^^^^^^^
  File "/home/jvalenti/miniforge3/envs/Parcels_24/lib/python3.11/site-packages/xarray/backends/file_manager.py", line 199, in acquire_context
    file, cached = self._acquire_with_cache_info(needs_lock)
                   ^^^^^^^^^^^^^^^^^^^^^^^^^^^^^^^^^^^^^^^^^
  File "/home/jvalenti/miniforge3/envs/Parcels_24/lib/python3.11/site-packages/xarray/backends/file_manager.py", line 217, in _acquire_with_cache_info
    file = self._opener(*self._args, **kwargs)
           ^^^^^^^^^^^^^^^^^^^^^^^^^^^^^^^^^^^
  File "src/netCDF4/_netCDF4.pyx", line 2469, in netCDF4._netCDF4.Dataset.__init__
  File "src/netCDF4/_netCDF4.pyx", line 2028, in netCDF4._netCDF4._ensure_nc_success
PermissionError: [Errno 13] Permission denied: '/home/jvalenti/projects/rrg-allen/jvalenti/restartruns/Parcels.nc'
Traceback (most recent call last):
  File "<frozen runpy>", line 198, in _run_module_as_main
  File "<frozen runpy>", line 88, in _run_code
  File "/home/jvalenti/MOAD/analysis-jose/Graham/Plastics_MCrestart.py", line 158, in <module>
    Restart_OP(config)
  File "/home/jvalenti/MOAD/analysis-jose/Graham/Plastics_MCrestart.py", line 138, in Restart_OP
    [xr.open_zarr(f) for f in files],
    ^^^^^^^^^^^^^^^^^^^^^^^^^^^^^^^^
  File "/home/jvalenti/MOAD/analysis-jose/Graham/Plastics_MCrestart.py", line 138, in <listcomp>
    [xr.open_zarr(f) for f in files],
     ^^^^^^^^^^^^^^^
  File "/home/jvalenti/miniforge3/envs/Parcels_24/lib/python3.11/site-packages/xarray/backends/zarr.py", line 944, in open_zarr
    ds = open_dataset(
         ^^^^^^^^^^^^^
  File "/home/jvalenti/miniforge3/envs/Parcels_24/lib/python3.11/site-packages/xarray/backends/api.py", line 572, in open_dataset
    backend_ds = backend.open_dataset(
                 ^^^^^^^^^^^^^^^^^^^^^
  File "/home/jvalenti/miniforge3/envs/Parcels_24/lib/python3.11/site-packages/xarray/backends/zarr.py", line 1026, in open_dataset
    ds = store_entrypoint.open_dataset(
         ^^^^^^^^^^^^^^^^^^^^^^^^^^^^^^
  File "/home/jvalenti/miniforge3/envs/Parcels_24/lib/python3.11/site-packages/xarray/backends/store.py", line 58, in open_dataset
    ds = Dataset(vars, attrs=attrs)
         ^^^^^^^^^^^^^^^^^^^^^^^^^^
  File "/home/jvalenti/miniforge3/envs/Parcels_24/lib/python3.11/site-packages/xarray/core/dataset.py", line 701, in __init__
    variables, coord_names, dims, indexes, _ = merge_data_and_coords(
                                               ^^^^^^^^^^^^^^^^^^^^^^
  File "/home/jvalenti/miniforge3/envs/Parcels_24/lib/python3.11/site-packages/xarray/core/dataset.py", line 430, in merge_data_and_coords
    return merge_core(
           ^^^^^^^^^^^
  File "/home/jvalenti/miniforge3/envs/Parcels_24/lib/python3.11/site-packages/xarray/core/merge.py", line 724, in merge_core
    dims = calculate_dimensions(variables)
           ^^^^^^^^^^^^^^^^^^^^^^^^^^^^^^^
  File "/home/jvalenti/miniforge3/envs/Parcels_24/lib/python3.11/site-packages/xarray/core/variable.py", line 3008, in calculate_dimensions
    raise ValueError(
ValueError: conflicting sizes for dimension 'obs': length 154 on 'diameter' and length 153 on {'trajectory': 'Ub', 'obs': 'Ub'}
Traceback (most recent call last):
  File "/home/jvalenti/miniforge3/envs/Parcels_24/lib/python3.11/site-packages/xarray/backends/file_manager.py", line 211, in _acquire_with_cache_info
    file = self._cache[self._key]
           ~~~~~~~~~~~^^^^^^^^^^^
  File "/home/jvalenti/miniforge3/envs/Parcels_24/lib/python3.11/site-packages/xarray/backends/lru_cache.py", line 56, in __getitem__
    value = self._cache[key]
            ~~~~~~~~~~~^^^^^
KeyError: [<class 'netCDF4._netCDF4.Dataset'>, ('/home/jvalenti/projects/rrg-allen/jvalenti/restartruns/Parcels.nc',), 'a', (('clobber', True), ('diskless', False), ('format', 'NETCDF4'), ('persist', False)), 'dc0364bd-eedb-44fa-95e9-4b9e1d0c9994']

During handling of the above exception, another exception occurred:

Traceback (most recent call last):
  File "<frozen runpy>", line 198, in _run_module_as_main
  File "<frozen runpy>", line 88, in _run_code
  File "/home/jvalenti/MOAD/analysis-jose/Graham/Plastics_MCrestart.py", line 158, in <module>
    Restart_OP(config)
  File "/home/jvalenti/MOAD/analysis-jose/Graham/Plastics_MCrestart.py", line 143, in Restart_OP
    ds.to_netcdf('/home/jvalenti/projects/rrg-allen/jvalenti/restart'+names+'.nc')
  File "/home/jvalenti/miniforge3/envs/Parcels_24/lib/python3.11/site-packages/xarray/core/dataset.py", line 2310, in to_netcdf
    return to_netcdf(  # type: ignore  # mypy cannot resolve the overloads:(
           ^^^^^^^^^^^^^^^^^^^^^^^^^^^^^^^^^^^^^^^^^^^^^^^^^^^^^^^^^^^^^^^^^
  File "/home/jvalenti/miniforge3/envs/Parcels_24/lib/python3.11/site-packages/xarray/backends/api.py", line 1298, in to_netcdf
    store = store_open(target, mode, format, group, **kwargs)
            ^^^^^^^^^^^^^^^^^^^^^^^^^^^^^^^^^^^^^^^^^^^^^^^^^
  File "/home/jvalenti/miniforge3/envs/Parcels_24/lib/python3.11/site-packages/xarray/backends/netCDF4_.py", line 400, in open
    return cls(manager, group=group, mode=mode, lock=lock, autoclose=autoclose)
           ^^^^^^^^^^^^^^^^^^^^^^^^^^^^^^^^^^^^^^^^^^^^^^^^^^^^^^^^^^^^^^^^^^^^
  File "/home/jvalenti/miniforge3/envs/Parcels_24/lib/python3.11/site-packages/xarray/backends/netCDF4_.py", line 347, in __init__
    self.format = self.ds.data_model
                  ^^^^^^^
  File "/home/jvalenti/miniforge3/envs/Parcels_24/lib/python3.11/site-packages/xarray/backends/netCDF4_.py", line 409, in ds
    return self._acquire()
           ^^^^^^^^^^^^^^^
  File "/home/jvalenti/miniforge3/envs/Parcels_24/lib/python3.11/site-packages/xarray/backends/netCDF4_.py", line 403, in _acquire
    with self._manager.acquire_context(needs_lock) as root:
  File "/home/jvalenti/miniforge3/envs/Parcels_24/lib/python3.11/contextlib.py", line 137, in __enter__
    return next(self.gen)
           ^^^^^^^^^^^^^^
  File "/home/jvalenti/miniforge3/envs/Parcels_24/lib/python3.11/site-packages/xarray/backends/file_manager.py", line 199, in acquire_context
    file, cached = self._acquire_with_cache_info(needs_lock)
                   ^^^^^^^^^^^^^^^^^^^^^^^^^^^^^^^^^^^^^^^^^
  File "/home/jvalenti/miniforge3/envs/Parcels_24/lib/python3.11/site-packages/xarray/backends/file_manager.py", line 217, in _acquire_with_cache_info
    file = self._opener(*self._args, **kwargs)
           ^^^^^^^^^^^^^^^^^^^^^^^^^^^^^^^^^^^
  File "src/netCDF4/_netCDF4.pyx", line 2469, in netCDF4._netCDF4.Dataset.__init__
  File "src/netCDF4/_netCDF4.pyx", line 2028, in netCDF4._netCDF4._ensure_nc_success
PermissionError: [Errno 13] Permission denied: '/home/jvalenti/projects/rrg-allen/jvalenti/restartruns/Parcels.nc'
Traceback (most recent call last):
  File "/home/jvalenti/miniforge3/envs/Parcels_24/lib/python3.11/site-packages/xarray/backends/file_manager.py", line 211, in _acquire_with_cache_info
    file = self._cache[self._key]
           ~~~~~~~~~~~^^^^^^^^^^^
  File "/home/jvalenti/miniforge3/envs/Parcels_24/lib/python3.11/site-packages/xarray/backends/lru_cache.py", line 56, in __getitem__
    value = self._cache[key]
            ~~~~~~~~~~~^^^^^
KeyError: [<class 'netCDF4._netCDF4.Dataset'>, ('/home/jvalenti/projects/rrg-allen/jvalenti/restartruns/Parcels.nc',), 'a', (('clobber', True), ('diskless', False), ('format', 'NETCDF4'), ('persist', False)), '42c9f2b3-2d9c-4f9f-94b3-ca711f617c33']

During handling of the above exception, another exception occurred:

Traceback (most recent call last):
  File "<frozen runpy>", line 198, in _run_module_as_main
  File "<frozen runpy>", line 88, in _run_code
  File "/home/jvalenti/MOAD/analysis-jose/Graham/Plastics_MCrestart.py", line 158, in <module>
    Restart_OP(config)
  File "/home/jvalenti/MOAD/analysis-jose/Graham/Plastics_MCrestart.py", line 143, in Restart_OP
    ds.to_netcdf('/home/jvalenti/projects/rrg-allen/jvalenti/restart'+names+'.nc')
  File "/home/jvalenti/miniforge3/envs/Parcels_24/lib/python3.11/site-packages/xarray/core/dataset.py", line 2310, in to_netcdf
    return to_netcdf(  # type: ignore  # mypy cannot resolve the overloads:(
           ^^^^^^^^^^^^^^^^^^^^^^^^^^^^^^^^^^^^^^^^^^^^^^^^^^^^^^^^^^^^^^^^^
  File "/home/jvalenti/miniforge3/envs/Parcels_24/lib/python3.11/site-packages/xarray/backends/api.py", line 1298, in to_netcdf
    store = store_open(target, mode, format, group, **kwargs)
            ^^^^^^^^^^^^^^^^^^^^^^^^^^^^^^^^^^^^^^^^^^^^^^^^^
  File "/home/jvalenti/miniforge3/envs/Parcels_24/lib/python3.11/site-packages/xarray/backends/netCDF4_.py", line 400, in open
    return cls(manager, group=group, mode=mode, lock=lock, autoclose=autoclose)
           ^^^^^^^^^^^^^^^^^^^^^^^^^^^^^^^^^^^^^^^^^^^^^^^^^^^^^^^^^^^^^^^^^^^^
  File "/home/jvalenti/miniforge3/envs/Parcels_24/lib/python3.11/site-packages/xarray/backends/netCDF4_.py", line 347, in __init__
    self.format = self.ds.data_model
                  ^^^^^^^
  File "/home/jvalenti/miniforge3/envs/Parcels_24/lib/python3.11/site-packages/xarray/backends/netCDF4_.py", line 409, in ds
    return self._acquire()
           ^^^^^^^^^^^^^^^
  File "/home/jvalenti/miniforge3/envs/Parcels_24/lib/python3.11/site-packages/xarray/backends/netCDF4_.py", line 403, in _acquire
    with self._manager.acquire_context(needs_lock) as root:
  File "/home/jvalenti/miniforge3/envs/Parcels_24/lib/python3.11/contextlib.py", line 137, in __enter__
    return next(self.gen)
           ^^^^^^^^^^^^^^
  File "/home/jvalenti/miniforge3/envs/Parcels_24/lib/python3.11/site-packages/xarray/backends/file_manager.py", line 199, in acquire_context
    file, cached = self._acquire_with_cache_info(needs_lock)
                   ^^^^^^^^^^^^^^^^^^^^^^^^^^^^^^^^^^^^^^^^^
  File "/home/jvalenti/miniforge3/envs/Parcels_24/lib/python3.11/site-packages/xarray/backends/file_manager.py", line 217, in _acquire_with_cache_info
    file = self._opener(*self._args, **kwargs)
           ^^^^^^^^^^^^^^^^^^^^^^^^^^^^^^^^^^^
  File "src/netCDF4/_netCDF4.pyx", line 2469, in netCDF4._netCDF4.Dataset.__init__
  File "src/netCDF4/_netCDF4.pyx", line 2028, in netCDF4._netCDF4._ensure_nc_success
PermissionError: [Errno 13] Permission denied: '/home/jvalenti/projects/rrg-allen/jvalenti/restartruns/Parcels.nc'
Traceback (most recent call last):
  File "/home/jvalenti/miniforge3/envs/Parcels_24/lib/python3.11/site-packages/xarray/backends/file_manager.py", line 211, in _acquire_with_cache_info
    file = self._cache[self._key]
           ~~~~~~~~~~~^^^^^^^^^^^
  File "/home/jvalenti/miniforge3/envs/Parcels_24/lib/python3.11/site-packages/xarray/backends/lru_cache.py", line 56, in __getitem__
    value = self._cache[key]
            ~~~~~~~~~~~^^^^^
KeyError: [<class 'netCDF4._netCDF4.Dataset'>, ('/home/jvalenti/projects/rrg-allen/jvalenti/restartruns/Parcels.nc',), 'a', (('clobber', True), ('diskless', False), ('format', 'NETCDF4'), ('persist', False)), 'e5c4003e-faef-4923-be62-58373da276a2']

During handling of the above exception, another exception occurred:

Traceback (most recent call last):
  File "<frozen runpy>", line 198, in _run_module_as_main
  File "<frozen runpy>", line 88, in _run_code
  File "/home/jvalenti/MOAD/analysis-jose/Graham/Plastics_MCrestart.py", line 158, in <module>
    Restart_OP(config)
  File "/home/jvalenti/MOAD/analysis-jose/Graham/Plastics_MCrestart.py", line 143, in Restart_OP
    ds.to_netcdf('/home/jvalenti/projects/rrg-allen/jvalenti/restart'+names+'.nc')
  File "/home/jvalenti/miniforge3/envs/Parcels_24/lib/python3.11/site-packages/xarray/core/dataset.py", line 2310, in to_netcdf
    return to_netcdf(  # type: ignore  # mypy cannot resolve the overloads:(
           ^^^^^^^^^^^^^^^^^^^^^^^^^^^^^^^^^^^^^^^^^^^^^^^^^^^^^^^^^^^^^^^^^
  File "/home/jvalenti/miniforge3/envs/Parcels_24/lib/python3.11/site-packages/xarray/backends/api.py", line 1298, in to_netcdf
    store = store_open(target, mode, format, group, **kwargs)
            ^^^^^^^^^^^^^^^^^^^^^^^^^^^^^^^^^^^^^^^^^^^^^^^^^
  File "/home/jvalenti/miniforge3/envs/Parcels_24/lib/python3.11/site-packages/xarray/backends/netCDF4_.py", line 400, in open
    return cls(manager, group=group, mode=mode, lock=lock, autoclose=autoclose)
           ^^^^^^^^^^^^^^^^^^^^^^^^^^^^^^^^^^^^^^^^^^^^^^^^^^^^^^^^^^^^^^^^^^^^
  File "/home/jvalenti/miniforge3/envs/Parcels_24/lib/python3.11/site-packages/xarray/backends/netCDF4_.py", line 347, in __init__
    self.format = self.ds.data_model
                  ^^^^^^^
  File "/home/jvalenti/miniforge3/envs/Parcels_24/lib/python3.11/site-packages/xarray/backends/netCDF4_.py", line 409, in ds
    return self._acquire()
           ^^^^^^^^^^^^^^^
  File "/home/jvalenti/miniforge3/envs/Parcels_24/lib/python3.11/site-packages/xarray/backends/netCDF4_.py", line 403, in _acquire
    with self._manager.acquire_context(needs_lock) as root:
  File "/home/jvalenti/miniforge3/envs/Parcels_24/lib/python3.11/contextlib.py", line 137, in __enter__
    return next(self.gen)
           ^^^^^^^^^^^^^^
  File "/home/jvalenti/miniforge3/envs/Parcels_24/lib/python3.11/site-packages/xarray/backends/file_manager.py", line 199, in acquire_context
    file, cached = self._acquire_with_cache_info(needs_lock)
                   ^^^^^^^^^^^^^^^^^^^^^^^^^^^^^^^^^^^^^^^^^
  File "/home/jvalenti/miniforge3/envs/Parcels_24/lib/python3.11/site-packages/xarray/backends/file_manager.py", line 217, in _acquire_with_cache_info
    file = self._opener(*self._args, **kwargs)
           ^^^^^^^^^^^^^^^^^^^^^^^^^^^^^^^^^^^
  File "src/netCDF4/_netCDF4.pyx", line 2469, in netCDF4._netCDF4.Dataset.__init__
  File "src/netCDF4/_netCDF4.pyx", line 2028, in netCDF4._netCDF4._ensure_nc_success
PermissionError: [Errno 13] Permission denied: '/home/jvalenti/projects/rrg-allen/jvalenti/restartruns/Parcels.nc'
Traceback (most recent call last):
  File "/home/jvalenti/miniforge3/envs/Parcels_24/lib/python3.11/site-packages/xarray/backends/file_manager.py", line 211, in _acquire_with_cache_info
    file = self._cache[self._key]
           ~~~~~~~~~~~^^^^^^^^^^^
  File "/home/jvalenti/miniforge3/envs/Parcels_24/lib/python3.11/site-packages/xarray/backends/lru_cache.py", line 56, in __getitem__
    value = self._cache[key]
            ~~~~~~~~~~~^^^^^
KeyError: [<class 'netCDF4._netCDF4.Dataset'>, ('/home/jvalenti/projects/rrg-allen/jvalenti/restartruns/Parcels.nc',), 'a', (('clobber', True), ('diskless', False), ('format', 'NETCDF4'), ('persist', False)), '16f22edc-2eda-4eb6-8642-01249533b924']

During handling of the above exception, another exception occurred:

Traceback (most recent call last):
  File "<frozen runpy>", line 198, in _run_module_as_main
  File "<frozen runpy>", line 88, in _run_code
  File "/home/jvalenti/MOAD/analysis-jose/Graham/Plastics_MCrestart.py", line 158, in <module>
    Restart_OP(config)
  File "/home/jvalenti/MOAD/analysis-jose/Graham/Plastics_MCrestart.py", line 143, in Restart_OP
    ds.to_netcdf('/home/jvalenti/projects/rrg-allen/jvalenti/restart'+names+'.nc')
  File "/home/jvalenti/miniforge3/envs/Parcels_24/lib/python3.11/site-packages/xarray/core/dataset.py", line 2310, in to_netcdf
    return to_netcdf(  # type: ignore  # mypy cannot resolve the overloads:(
           ^^^^^^^^^^^^^^^^^^^^^^^^^^^^^^^^^^^^^^^^^^^^^^^^^^^^^^^^^^^^^^^^^
  File "/home/jvalenti/miniforge3/envs/Parcels_24/lib/python3.11/site-packages/xarray/backends/api.py", line 1298, in to_netcdf
    store = store_open(target, mode, format, group, **kwargs)
            ^^^^^^^^^^^^^^^^^^^^^^^^^^^^^^^^^^^^^^^^^^^^^^^^^
  File "/home/jvalenti/miniforge3/envs/Parcels_24/lib/python3.11/site-packages/xarray/backends/netCDF4_.py", line 400, in open
    return cls(manager, group=group, mode=mode, lock=lock, autoclose=autoclose)
           ^^^^^^^^^^^^^^^^^^^^^^^^^^^^^^^^^^^^^^^^^^^^^^^^^^^^^^^^^^^^^^^^^^^^
  File "/home/jvalenti/miniforge3/envs/Parcels_24/lib/python3.11/site-packages/xarray/backends/netCDF4_.py", line 347, in __init__
    self.format = self.ds.data_model
                  ^^^^^^^
  File "/home/jvalenti/miniforge3/envs/Parcels_24/lib/python3.11/site-packages/xarray/backends/netCDF4_.py", line 409, in ds
    return self._acquire()
           ^^^^^^^^^^^^^^^
  File "/home/jvalenti/miniforge3/envs/Parcels_24/lib/python3.11/site-packages/xarray/backends/netCDF4_.py", line 403, in _acquire
    with self._manager.acquire_context(needs_lock) as root:
  File "/home/jvalenti/miniforge3/envs/Parcels_24/lib/python3.11/contextlib.py", line 137, in __enter__
    return next(self.gen)
           ^^^^^^^^^^^^^^
  File "/home/jvalenti/miniforge3/envs/Parcels_24/lib/python3.11/site-packages/xarray/backends/file_manager.py", line 199, in acquire_context
    file, cached = self._acquire_with_cache_info(needs_lock)
                   ^^^^^^^^^^^^^^^^^^^^^^^^^^^^^^^^^^^^^^^^^
  File "/home/jvalenti/miniforge3/envs/Parcels_24/lib/python3.11/site-packages/xarray/backends/file_manager.py", line 217, in _acquire_with_cache_info
    file = self._opener(*self._args, **kwargs)
           ^^^^^^^^^^^^^^^^^^^^^^^^^^^^^^^^^^^
  File "src/netCDF4/_netCDF4.pyx", line 2469, in netCDF4._netCDF4.Dataset.__init__
  File "src/netCDF4/_netCDF4.pyx", line 2028, in netCDF4._netCDF4._ensure_nc_success
PermissionError: [Errno 13] Permission denied: '/home/jvalenti/projects/rrg-allen/jvalenti/restartruns/Parcels.nc'
Traceback (most recent call last):
  File "/home/jvalenti/miniforge3/envs/Parcels_24/lib/python3.11/site-packages/xarray/backends/file_manager.py", line 211, in _acquire_with_cache_info
    file = self._cache[self._key]
           ~~~~~~~~~~~^^^^^^^^^^^
  File "/home/jvalenti/miniforge3/envs/Parcels_24/lib/python3.11/site-packages/xarray/backends/lru_cache.py", line 56, in __getitem__
    value = self._cache[key]
            ~~~~~~~~~~~^^^^^
KeyError: [<class 'netCDF4._netCDF4.Dataset'>, ('/home/jvalenti/projects/rrg-allen/jvalenti/restartruns/Parcels.nc',), 'a', (('clobber', True), ('diskless', False), ('format', 'NETCDF4'), ('persist', False)), '0ff0959b-987c-4512-9f5d-1e8b82ee06da']

During handling of the above exception, another exception occurred:

Traceback (most recent call last):
  File "<frozen runpy>", line 198, in _run_module_as_main
  File "<frozen runpy>", line 88, in _run_code
  File "/home/jvalenti/MOAD/analysis-jose/Graham/Plastics_MCrestart.py", line 158, in <module>
    Restart_OP(config)
  File "/home/jvalenti/MOAD/analysis-jose/Graham/Plastics_MCrestart.py", line 143, in Restart_OP
    ds.to_netcdf('/home/jvalenti/projects/rrg-allen/jvalenti/restart'+names+'.nc')
  File "/home/jvalenti/miniforge3/envs/Parcels_24/lib/python3.11/site-packages/xarray/core/dataset.py", line 2310, in to_netcdf
    return to_netcdf(  # type: ignore  # mypy cannot resolve the overloads:(
           ^^^^^^^^^^^^^^^^^^^^^^^^^^^^^^^^^^^^^^^^^^^^^^^^^^^^^^^^^^^^^^^^^
  File "/home/jvalenti/miniforge3/envs/Parcels_24/lib/python3.11/site-packages/xarray/backends/api.py", line 1298, in to_netcdf
    store = store_open(target, mode, format, group, **kwargs)
            ^^^^^^^^^^^^^^^^^^^^^^^^^^^^^^^^^^^^^^^^^^^^^^^^^
  File "/home/jvalenti/miniforge3/envs/Parcels_24/lib/python3.11/site-packages/xarray/backends/netCDF4_.py", line 400, in open
    return cls(manager, group=group, mode=mode, lock=lock, autoclose=autoclose)
           ^^^^^^^^^^^^^^^^^^^^^^^^^^^^^^^^^^^^^^^^^^^^^^^^^^^^^^^^^^^^^^^^^^^^
  File "/home/jvalenti/miniforge3/envs/Parcels_24/lib/python3.11/site-packages/xarray/backends/netCDF4_.py", line 347, in __init__
    self.format = self.ds.data_model
                  ^^^^^^^
  File "/home/jvalenti/miniforge3/envs/Parcels_24/lib/python3.11/site-packages/xarray/backends/netCDF4_.py", line 409, in ds
    return self._acquire()
           ^^^^^^^^^^^^^^^
  File "/home/jvalenti/miniforge3/envs/Parcels_24/lib/python3.11/site-packages/xarray/backends/netCDF4_.py", line 403, in _acquire
    with self._manager.acquire_context(needs_lock) as root:
  File "/home/jvalenti/miniforge3/envs/Parcels_24/lib/python3.11/contextlib.py", line 137, in __enter__
    return next(self.gen)
           ^^^^^^^^^^^^^^
  File "/home/jvalenti/miniforge3/envs/Parcels_24/lib/python3.11/site-packages/xarray/backends/file_manager.py", line 199, in acquire_context
    file, cached = self._acquire_with_cache_info(needs_lock)
                   ^^^^^^^^^^^^^^^^^^^^^^^^^^^^^^^^^^^^^^^^^
  File "/home/jvalenti/miniforge3/envs/Parcels_24/lib/python3.11/site-packages/xarray/backends/file_manager.py", line 217, in _acquire_with_cache_info
    file = self._opener(*self._args, **kwargs)
           ^^^^^^^^^^^^^^^^^^^^^^^^^^^^^^^^^^^
  File "src/netCDF4/_netCDF4.pyx", line 2469, in netCDF4._netCDF4.Dataset.__init__
  File "src/netCDF4/_netCDF4.pyx", line 2028, in netCDF4._netCDF4._ensure_nc_success
PermissionError: [Errno 13] Permission denied: '/home/jvalenti/projects/rrg-allen/jvalenti/restartruns/Parcels.nc'
Traceback (most recent call last):
  File "/home/jvalenti/miniforge3/envs/Parcels_24/lib/python3.11/site-packages/xarray/backends/file_manager.py", line 211, in _acquire_with_cache_info
    file = self._cache[self._key]
           ~~~~~~~~~~~^^^^^^^^^^^
  File "/home/jvalenti/miniforge3/envs/Parcels_24/lib/python3.11/site-packages/xarray/backends/lru_cache.py", line 56, in __getitem__
    value = self._cache[key]
            ~~~~~~~~~~~^^^^^
KeyError: [<class 'netCDF4._netCDF4.Dataset'>, ('/home/jvalenti/projects/rrg-allen/jvalenti/restartruns/Parcels.nc',), 'a', (('clobber', True), ('diskless', False), ('format', 'NETCDF4'), ('persist', False)), 'b3e656a1-1e2e-4274-9aee-e634e01446fa']

During handling of the above exception, another exception occurred:

Traceback (most recent call last):
  File "<frozen runpy>", line 198, in _run_module_as_main
  File "<frozen runpy>", line 88, in _run_code
  File "/home/jvalenti/MOAD/analysis-jose/Graham/Plastics_MCrestart.py", line 158, in <module>
    Restart_OP(config)
  File "/home/jvalenti/MOAD/analysis-jose/Graham/Plastics_MCrestart.py", line 143, in Restart_OP
    ds.to_netcdf('/home/jvalenti/projects/rrg-allen/jvalenti/restart'+names+'.nc')
  File "/home/jvalenti/miniforge3/envs/Parcels_24/lib/python3.11/site-packages/xarray/core/dataset.py", line 2310, in to_netcdf
    return to_netcdf(  # type: ignore  # mypy cannot resolve the overloads:(
           ^^^^^^^^^^^^^^^^^^^^^^^^^^^^^^^^^^^^^^^^^^^^^^^^^^^^^^^^^^^^^^^^^
  File "/home/jvalenti/miniforge3/envs/Parcels_24/lib/python3.11/site-packages/xarray/backends/api.py", line 1298, in to_netcdf
    store = store_open(target, mode, format, group, **kwargs)
            ^^^^^^^^^^^^^^^^^^^^^^^^^^^^^^^^^^^^^^^^^^^^^^^^^
  File "/home/jvalenti/miniforge3/envs/Parcels_24/lib/python3.11/site-packages/xarray/backends/netCDF4_.py", line 400, in open
    return cls(manager, group=group, mode=mode, lock=lock, autoclose=autoclose)
           ^^^^^^^^^^^^^^^^^^^^^^^^^^^^^^^^^^^^^^^^^^^^^^^^^^^^^^^^^^^^^^^^^^^^
  File "/home/jvalenti/miniforge3/envs/Parcels_24/lib/python3.11/site-packages/xarray/backends/netCDF4_.py", line 347, in __init__
    self.format = self.ds.data_model
                  ^^^^^^^
  File "/home/jvalenti/miniforge3/envs/Parcels_24/lib/python3.11/site-packages/xarray/backends/netCDF4_.py", line 409, in ds
    return self._acquire()
           ^^^^^^^^^^^^^^^
  File "/home/jvalenti/miniforge3/envs/Parcels_24/lib/python3.11/site-packages/xarray/backends/netCDF4_.py", line 403, in _acquire
    with self._manager.acquire_context(needs_lock) as root:
  File "/home/jvalenti/miniforge3/envs/Parcels_24/lib/python3.11/contextlib.py", line 137, in __enter__
    return next(self.gen)
           ^^^^^^^^^^^^^^
  File "/home/jvalenti/miniforge3/envs/Parcels_24/lib/python3.11/site-packages/xarray/backends/file_manager.py", line 199, in acquire_context
    file, cached = self._acquire_with_cache_info(needs_lock)
                   ^^^^^^^^^^^^^^^^^^^^^^^^^^^^^^^^^^^^^^^^^
  File "/home/jvalenti/miniforge3/envs/Parcels_24/lib/python3.11/site-packages/xarray/backends/file_manager.py", line 217, in _acquire_with_cache_info
    file = self._opener(*self._args, **kwargs)
           ^^^^^^^^^^^^^^^^^^^^^^^^^^^^^^^^^^^
  File "src/netCDF4/_netCDF4.pyx", line 2469, in netCDF4._netCDF4.Dataset.__init__
  File "src/netCDF4/_netCDF4.pyx", line 2028, in netCDF4._netCDF4._ensure_nc_success
PermissionError: [Errno 13] Permission denied: '/home/jvalenti/projects/rrg-allen/jvalenti/restartruns/Parcels.nc'
Traceback (most recent call last):
  File "/home/jvalenti/miniforge3/envs/Parcels_24/lib/python3.11/site-packages/xarray/backends/file_manager.py", line 211, in _acquire_with_cache_info
    file = self._cache[self._key]
           ~~~~~~~~~~~^^^^^^^^^^^
  File "/home/jvalenti/miniforge3/envs/Parcels_24/lib/python3.11/site-packages/xarray/backends/lru_cache.py", line 56, in __getitem__
    value = self._cache[key]
            ~~~~~~~~~~~^^^^^
KeyError: [<class 'netCDF4._netCDF4.Dataset'>, ('/home/jvalenti/projects/rrg-allen/jvalenti/restartruns/Parcels.nc',), 'a', (('clobber', True), ('diskless', False), ('format', 'NETCDF4'), ('persist', False)), 'e6fc6e59-2ad7-4ee8-863f-a10b56714c21']

During handling of the above exception, another exception occurred:

Traceback (most recent call last):
  File "<frozen runpy>", line 198, in _run_module_as_main
  File "<frozen runpy>", line 88, in _run_code
  File "/home/jvalenti/MOAD/analysis-jose/Graham/Plastics_MCrestart.py", line 158, in <module>
    Restart_OP(config)
  File "/home/jvalenti/MOAD/analysis-jose/Graham/Plastics_MCrestart.py", line 143, in Restart_OP
    ds.to_netcdf('/home/jvalenti/projects/rrg-allen/jvalenti/restart'+names+'.nc')
  File "/home/jvalenti/miniforge3/envs/Parcels_24/lib/python3.11/site-packages/xarray/core/dataset.py", line 2310, in to_netcdf
    return to_netcdf(  # type: ignore  # mypy cannot resolve the overloads:(
           ^^^^^^^^^^^^^^^^^^^^^^^^^^^^^^^^^^^^^^^^^^^^^^^^^^^^^^^^^^^^^^^^^
  File "/home/jvalenti/miniforge3/envs/Parcels_24/lib/python3.11/site-packages/xarray/backends/api.py", line 1298, in to_netcdf
    store = store_open(target, mode, format, group, **kwargs)
            ^^^^^^^^^^^^^^^^^^^^^^^^^^^^^^^^^^^^^^^^^^^^^^^^^
  File "/home/jvalenti/miniforge3/envs/Parcels_24/lib/python3.11/site-packages/xarray/backends/netCDF4_.py", line 400, in open
    return cls(manager, group=group, mode=mode, lock=lock, autoclose=autoclose)
           ^^^^^^^^^^^^^^^^^^^^^^^^^^^^^^^^^^^^^^^^^^^^^^^^^^^^^^^^^^^^^^^^^^^^
  File "/home/jvalenti/miniforge3/envs/Parcels_24/lib/python3.11/site-packages/xarray/backends/netCDF4_.py", line 347, in __init__
    self.format = self.ds.data_model
                  ^^^^^^^
  File "/home/jvalenti/miniforge3/envs/Parcels_24/lib/python3.11/site-packages/xarray/backends/netCDF4_.py", line 409, in ds
    return self._acquire()
           ^^^^^^^^^^^^^^^
  File "/home/jvalenti/miniforge3/envs/Parcels_24/lib/python3.11/site-packages/xarray/backends/netCDF4_.py", line 403, in _acquire
    with self._manager.acquire_context(needs_lock) as root:
  File "/home/jvalenti/miniforge3/envs/Parcels_24/lib/python3.11/contextlib.py", line 137, in __enter__
    return next(self.gen)
           ^^^^^^^^^^^^^^
  File "/home/jvalenti/miniforge3/envs/Parcels_24/lib/python3.11/site-packages/xarray/backends/file_manager.py", line 199, in acquire_context
    file, cached = self._acquire_with_cache_info(needs_lock)
                   ^^^^^^^^^^^^^^^^^^^^^^^^^^^^^^^^^^^^^^^^^
  File "/home/jvalenti/miniforge3/envs/Parcels_24/lib/python3.11/site-packages/xarray/backends/file_manager.py", line 217, in _acquire_with_cache_info
    file = self._opener(*self._args, **kwargs)
           ^^^^^^^^^^^^^^^^^^^^^^^^^^^^^^^^^^^
  File "src/netCDF4/_netCDF4.pyx", line 2469, in netCDF4._netCDF4.Dataset.__init__
  File "src/netCDF4/_netCDF4.pyx", line 2028, in netCDF4._netCDF4._ensure_nc_success
PermissionError: [Errno 13] Permission denied: '/home/jvalenti/projects/rrg-allen/jvalenti/restartruns/Parcels.nc'
